WARNING:fake_useragent:Error occurred during loading data. Trying to use cache server https://fake-useragent.herokuapp.com/browsers/0.1.8
Traceback (most recent call last):
  File "/home/morteza/anaconda3/lib/python3.6/urllib/request.py", line 1318, in do_open
    encode_chunked=req.has_header('Transfer-encoding'))
  File "/home/morteza/anaconda3/lib/python3.6/http/client.py", line 1239, in request
    self._send_request(method, url, body, headers, encode_chunked)
  File "/home/morteza/anaconda3/lib/python3.6/http/client.py", line 1285, in _send_request
    self.endheaders(body, encode_chunked=encode_chunked)
  File "/home/morteza/anaconda3/lib/python3.6/http/client.py", line 1234, in endheaders
    self._send_output(message_body, encode_chunked=encode_chunked)
  File "/home/morteza/anaconda3/lib/python3.6/http/client.py", line 1026, in _send_output
    self.send(msg)
  File "/home/morteza/anaconda3/lib/python3.6/http/client.py", line 964, in send
    self.connect()
  File "/home/morteza/anaconda3/lib/python3.6/http/client.py", line 936, in connect
    (self.host,self.port), self.timeout, self.source_address)
  File "/home/morteza/anaconda3/lib/python3.6/socket.py", line 722, in create_connection
    raise err
  File "/home/morteza/anaconda3/lib/python3.6/socket.py", line 713, in create_connection
    sock.connect(sa)
socket.timeout: timed out

During handling of the above exception, another exception occurred:

Traceback (most recent call last):
  File "/home/morteza/anaconda3/lib/python3.6/site-packages/fake_useragent/utils.py", line 67, in get
    context=context,
  File "/home/morteza/anaconda3/lib/python3.6/urllib/request.py", line 223, in urlopen
    return opener.open(url, data, timeout)
  File "/home/morteza/anaconda3/lib/python3.6/urllib/request.py", line 526, in open
    response = self._open(req, data)
  File "/home/morteza/anaconda3/lib/python3.6/urllib/request.py", line 544, in _open
    '_open', req)
  File "/home/morteza/anaconda3/lib/python3.6/urllib/request.py", line 504, in _call_chain
    result = func(*args)
  File "/home/morteza/anaconda3/lib/python3.6/urllib/request.py", line 1346, in http_open
    return self.do_open(http.client.HTTPConnection, req)
  File "/home/morteza/anaconda3/lib/python3.6/urllib/request.py", line 1320, in do_open
    raise URLError(err)
urllib.error.URLError: <urlopen error timed out>

During handling of the above exception, another exception occurred:

Traceback (most recent call last):
  File "/home/morteza/anaconda3/lib/python3.6/site-packages/fake_useragent/utils.py", line 166, in load
    verify_ssl=verify_ssl,
  File "/home/morteza/anaconda3/lib/python3.6/site-packages/fake_useragent/utils.py", line 122, in get_browser_versions
    verify_ssl=verify_ssl,
  File "/home/morteza/anaconda3/lib/python3.6/site-packages/fake_useragent/utils.py", line 84, in get
    raise FakeUserAgentError('Maximum amount of retries reached')
fake_useragent.errors.FakeUserAgentError: Maximum amount of retries reached
ERROR:root:Except on like!
Traceback (most recent call last):
  File "/home/morteza/anaconda3/lib/python3.6/site-packages/requests/packages/urllib3/connectionpool.py", line 600, in urlopen
    chunked=chunked)
  File "/home/morteza/anaconda3/lib/python3.6/site-packages/requests/packages/urllib3/connectionpool.py", line 386, in _make_request
    six.raise_from(e, None)
  File "<string>", line 2, in raise_from
  File "/home/morteza/anaconda3/lib/python3.6/site-packages/requests/packages/urllib3/connectionpool.py", line 382, in _make_request
    httplib_response = conn.getresponse()
  File "/home/morteza/anaconda3/lib/python3.6/http/client.py", line 1331, in getresponse
    response.begin()
  File "/home/morteza/anaconda3/lib/python3.6/http/client.py", line 297, in begin
    version, status, reason = self._read_status()
  File "/home/morteza/anaconda3/lib/python3.6/http/client.py", line 258, in _read_status
    line = str(self.fp.readline(_MAXLINE + 1), "iso-8859-1")
  File "/home/morteza/anaconda3/lib/python3.6/socket.py", line 586, in readinto
    return self._sock.recv_into(b)
  File "/home/morteza/anaconda3/lib/python3.6/site-packages/requests/packages/urllib3/contrib/pyopenssl.py", line 282, in recv_into
    raise SocketError(str(e))
OSError: (110, 'ETIMEDOUT')

During handling of the above exception, another exception occurred:

Traceback (most recent call last):
  File "/home/morteza/anaconda3/lib/python3.6/site-packages/requests/adapters.py", line 423, in send
    timeout=timeout
  File "/home/morteza/anaconda3/lib/python3.6/site-packages/requests/packages/urllib3/connectionpool.py", line 649, in urlopen
    _stacktrace=sys.exc_info()[2])
  File "/home/morteza/anaconda3/lib/python3.6/site-packages/requests/packages/urllib3/util/retry.py", line 347, in increment
    raise six.reraise(type(error), error, _stacktrace)
  File "/home/morteza/anaconda3/lib/python3.6/site-packages/requests/packages/urllib3/packages/six.py", line 685, in reraise
    raise value.with_traceback(tb)
  File "/home/morteza/anaconda3/lib/python3.6/site-packages/requests/packages/urllib3/connectionpool.py", line 600, in urlopen
    chunked=chunked)
  File "/home/morteza/anaconda3/lib/python3.6/site-packages/requests/packages/urllib3/connectionpool.py", line 386, in _make_request
    six.raise_from(e, None)
  File "<string>", line 2, in raise_from
  File "/home/morteza/anaconda3/lib/python3.6/site-packages/requests/packages/urllib3/connectionpool.py", line 382, in _make_request
    httplib_response = conn.getresponse()
  File "/home/morteza/anaconda3/lib/python3.6/http/client.py", line 1331, in getresponse
    response.begin()
  File "/home/morteza/anaconda3/lib/python3.6/http/client.py", line 297, in begin
    version, status, reason = self._read_status()
  File "/home/morteza/anaconda3/lib/python3.6/http/client.py", line 258, in _read_status
    line = str(self.fp.readline(_MAXLINE + 1), "iso-8859-1")
  File "/home/morteza/anaconda3/lib/python3.6/socket.py", line 586, in readinto
    return self._sock.recv_into(b)
  File "/home/morteza/anaconda3/lib/python3.6/site-packages/requests/packages/urllib3/contrib/pyopenssl.py", line 282, in recv_into
    raise SocketError(str(e))
requests.packages.urllib3.exceptions.ProtocolError: ('Connection aborted.', OSError("(110, 'ETIMEDOUT')",))

During handling of the above exception, another exception occurred:

Traceback (most recent call last):
  File "/home/morteza/Code/instabot.py/src/instabot.py", line 569, in like
    like = self.s.post(url_likes)
  File "/home/morteza/anaconda3/lib/python3.6/site-packages/requests/sessions.py", line 535, in post
    return self.request('POST', url, data=data, json=json, **kwargs)
  File "/home/morteza/anaconda3/lib/python3.6/site-packages/requests/sessions.py", line 488, in request
    resp = self.send(prep, **send_kwargs)
  File "/home/morteza/anaconda3/lib/python3.6/site-packages/requests/sessions.py", line 609, in send
    r = adapter.send(request, **kwargs)
  File "/home/morteza/anaconda3/lib/python3.6/site-packages/requests/adapters.py", line 473, in send
    raise ConnectionError(err, request=request)
requests.exceptions.ConnectionError: ('Connection aborted.', OSError("(110, 'ETIMEDOUT')",))
ERROR:root:Except on like!
Traceback (most recent call last):
  File "/home/morteza/anaconda3/lib/python3.6/site-packages/requests/packages/urllib3/connection.py", line 141, in _new_conn
    (self.host, self.port), self.timeout, **extra_kw)
  File "/home/morteza/anaconda3/lib/python3.6/site-packages/requests/packages/urllib3/util/connection.py", line 60, in create_connection
    for res in socket.getaddrinfo(host, port, family, socket.SOCK_STREAM):
  File "/home/morteza/anaconda3/lib/python3.6/socket.py", line 743, in getaddrinfo
    for res in _socket.getaddrinfo(host, port, family, type, proto, flags):
socket.gaierror: [Errno -2] Name or service not known

During handling of the above exception, another exception occurred:

Traceback (most recent call last):
  File "/home/morteza/anaconda3/lib/python3.6/site-packages/requests/packages/urllib3/connectionpool.py", line 600, in urlopen
    chunked=chunked)
  File "/home/morteza/anaconda3/lib/python3.6/site-packages/requests/packages/urllib3/connectionpool.py", line 345, in _make_request
    self._validate_conn(conn)
  File "/home/morteza/anaconda3/lib/python3.6/site-packages/requests/packages/urllib3/connectionpool.py", line 844, in _validate_conn
    conn.connect()
  File "/home/morteza/anaconda3/lib/python3.6/site-packages/requests/packages/urllib3/connection.py", line 284, in connect
    conn = self._new_conn()
  File "/home/morteza/anaconda3/lib/python3.6/site-packages/requests/packages/urllib3/connection.py", line 150, in _new_conn
    self, "Failed to establish a new connection: %s" % e)
requests.packages.urllib3.exceptions.NewConnectionError: <requests.packages.urllib3.connection.VerifiedHTTPSConnection object at 0x7f65b0b00080>: Failed to establish a new connection: [Errno -2] Name or service not known

During handling of the above exception, another exception occurred:

Traceback (most recent call last):
  File "/home/morteza/anaconda3/lib/python3.6/site-packages/requests/adapters.py", line 423, in send
    timeout=timeout
  File "/home/morteza/anaconda3/lib/python3.6/site-packages/requests/packages/urllib3/connectionpool.py", line 649, in urlopen
    _stacktrace=sys.exc_info()[2])
  File "/home/morteza/anaconda3/lib/python3.6/site-packages/requests/packages/urllib3/util/retry.py", line 376, in increment
    raise MaxRetryError(_pool, url, error or ResponseError(cause))
requests.packages.urllib3.exceptions.MaxRetryError: HTTPSConnectionPool(host='www.instagram.com', port=443): Max retries exceeded with url: /web/likes/1704782333247074991/like/ (Caused by NewConnectionError('<requests.packages.urllib3.connection.VerifiedHTTPSConnection object at 0x7f65b0b00080>: Failed to establish a new connection: [Errno -2] Name or service not known',))

During handling of the above exception, another exception occurred:

Traceback (most recent call last):
  File "/home/morteza/Code/instabot.py/src/instabot.py", line 569, in like
    like = self.s.post(url_likes)
  File "/home/morteza/anaconda3/lib/python3.6/site-packages/requests/sessions.py", line 535, in post
    return self.request('POST', url, data=data, json=json, **kwargs)
  File "/home/morteza/anaconda3/lib/python3.6/site-packages/requests/sessions.py", line 488, in request
    resp = self.send(prep, **send_kwargs)
  File "/home/morteza/anaconda3/lib/python3.6/site-packages/requests/sessions.py", line 609, in send
    r = adapter.send(request, **kwargs)
  File "/home/morteza/anaconda3/lib/python3.6/site-packages/requests/adapters.py", line 487, in send
    raise ConnectionError(e, request=request)
requests.exceptions.ConnectionError: HTTPSConnectionPool(host='www.instagram.com', port=443): Max retries exceeded with url: /web/likes/1704782333247074991/like/ (Caused by NewConnectionError('<requests.packages.urllib3.connection.VerifiedHTTPSConnection object at 0x7f65b0b00080>: Failed to establish a new connection: [Errno -2] Name or service not known',))
ERROR:root:Except on like!
Traceback (most recent call last):
  File "/home/morteza/anaconda3/lib/python3.6/site-packages/requests/packages/urllib3/connection.py", line 141, in _new_conn
    (self.host, self.port), self.timeout, **extra_kw)
  File "/home/morteza/anaconda3/lib/python3.6/site-packages/requests/packages/urllib3/util/connection.py", line 60, in create_connection
    for res in socket.getaddrinfo(host, port, family, socket.SOCK_STREAM):
  File "/home/morteza/anaconda3/lib/python3.6/socket.py", line 743, in getaddrinfo
    for res in _socket.getaddrinfo(host, port, family, type, proto, flags):
socket.gaierror: [Errno -2] Name or service not known

During handling of the above exception, another exception occurred:

Traceback (most recent call last):
  File "/home/morteza/anaconda3/lib/python3.6/site-packages/requests/packages/urllib3/connectionpool.py", line 600, in urlopen
    chunked=chunked)
  File "/home/morteza/anaconda3/lib/python3.6/site-packages/requests/packages/urllib3/connectionpool.py", line 345, in _make_request
    self._validate_conn(conn)
  File "/home/morteza/anaconda3/lib/python3.6/site-packages/requests/packages/urllib3/connectionpool.py", line 844, in _validate_conn
    conn.connect()
  File "/home/morteza/anaconda3/lib/python3.6/site-packages/requests/packages/urllib3/connection.py", line 284, in connect
    conn = self._new_conn()
  File "/home/morteza/anaconda3/lib/python3.6/site-packages/requests/packages/urllib3/connection.py", line 150, in _new_conn
    self, "Failed to establish a new connection: %s" % e)
requests.packages.urllib3.exceptions.NewConnectionError: <requests.packages.urllib3.connection.VerifiedHTTPSConnection object at 0x7f65b0aeaf60>: Failed to establish a new connection: [Errno -2] Name or service not known

During handling of the above exception, another exception occurred:

Traceback (most recent call last):
  File "/home/morteza/anaconda3/lib/python3.6/site-packages/requests/adapters.py", line 423, in send
    timeout=timeout
  File "/home/morteza/anaconda3/lib/python3.6/site-packages/requests/packages/urllib3/connectionpool.py", line 649, in urlopen
    _stacktrace=sys.exc_info()[2])
  File "/home/morteza/anaconda3/lib/python3.6/site-packages/requests/packages/urllib3/util/retry.py", line 376, in increment
    raise MaxRetryError(_pool, url, error or ResponseError(cause))
requests.packages.urllib3.exceptions.MaxRetryError: HTTPSConnectionPool(host='www.instagram.com', port=443): Max retries exceeded with url: /web/likes/1704726792927313179/like/ (Caused by NewConnectionError('<requests.packages.urllib3.connection.VerifiedHTTPSConnection object at 0x7f65b0aeaf60>: Failed to establish a new connection: [Errno -2] Name or service not known',))

During handling of the above exception, another exception occurred:

Traceback (most recent call last):
  File "/home/morteza/Code/instabot.py/src/instabot.py", line 569, in like
    like = self.s.post(url_likes)
  File "/home/morteza/anaconda3/lib/python3.6/site-packages/requests/sessions.py", line 535, in post
    return self.request('POST', url, data=data, json=json, **kwargs)
  File "/home/morteza/anaconda3/lib/python3.6/site-packages/requests/sessions.py", line 488, in request
    resp = self.send(prep, **send_kwargs)
  File "/home/morteza/anaconda3/lib/python3.6/site-packages/requests/sessions.py", line 609, in send
    r = adapter.send(request, **kwargs)
  File "/home/morteza/anaconda3/lib/python3.6/site-packages/requests/adapters.py", line 487, in send
    raise ConnectionError(e, request=request)
requests.exceptions.ConnectionError: HTTPSConnectionPool(host='www.instagram.com', port=443): Max retries exceeded with url: /web/likes/1704726792927313179/like/ (Caused by NewConnectionError('<requests.packages.urllib3.connection.VerifiedHTTPSConnection object at 0x7f65b0aeaf60>: Failed to establish a new connection: [Errno -2] Name or service not known',))
ERROR:root:Except on like!
Traceback (most recent call last):
  File "/home/morteza/anaconda3/lib/python3.6/site-packages/requests/packages/urllib3/connection.py", line 141, in _new_conn
    (self.host, self.port), self.timeout, **extra_kw)
  File "/home/morteza/anaconda3/lib/python3.6/site-packages/requests/packages/urllib3/util/connection.py", line 60, in create_connection
    for res in socket.getaddrinfo(host, port, family, socket.SOCK_STREAM):
  File "/home/morteza/anaconda3/lib/python3.6/socket.py", line 743, in getaddrinfo
    for res in _socket.getaddrinfo(host, port, family, type, proto, flags):
socket.gaierror: [Errno -2] Name or service not known

During handling of the above exception, another exception occurred:

Traceback (most recent call last):
  File "/home/morteza/anaconda3/lib/python3.6/site-packages/requests/packages/urllib3/connectionpool.py", line 600, in urlopen
    chunked=chunked)
  File "/home/morteza/anaconda3/lib/python3.6/site-packages/requests/packages/urllib3/connectionpool.py", line 345, in _make_request
    self._validate_conn(conn)
  File "/home/morteza/anaconda3/lib/python3.6/site-packages/requests/packages/urllib3/connectionpool.py", line 844, in _validate_conn
    conn.connect()
  File "/home/morteza/anaconda3/lib/python3.6/site-packages/requests/packages/urllib3/connection.py", line 284, in connect
    conn = self._new_conn()
  File "/home/morteza/anaconda3/lib/python3.6/site-packages/requests/packages/urllib3/connection.py", line 150, in _new_conn
    self, "Failed to establish a new connection: %s" % e)
requests.packages.urllib3.exceptions.NewConnectionError: <requests.packages.urllib3.connection.VerifiedHTTPSConnection object at 0x7f65b0b00080>: Failed to establish a new connection: [Errno -2] Name or service not known

During handling of the above exception, another exception occurred:

Traceback (most recent call last):
  File "/home/morteza/anaconda3/lib/python3.6/site-packages/requests/adapters.py", line 423, in send
    timeout=timeout
  File "/home/morteza/anaconda3/lib/python3.6/site-packages/requests/packages/urllib3/connectionpool.py", line 649, in urlopen
    _stacktrace=sys.exc_info()[2])
  File "/home/morteza/anaconda3/lib/python3.6/site-packages/requests/packages/urllib3/util/retry.py", line 376, in increment
    raise MaxRetryError(_pool, url, error or ResponseError(cause))
requests.packages.urllib3.exceptions.MaxRetryError: HTTPSConnectionPool(host='www.instagram.com', port=443): Max retries exceeded with url: /web/likes/1704726188460920426/like/ (Caused by NewConnectionError('<requests.packages.urllib3.connection.VerifiedHTTPSConnection object at 0x7f65b0b00080>: Failed to establish a new connection: [Errno -2] Name or service not known',))

During handling of the above exception, another exception occurred:

Traceback (most recent call last):
  File "/home/morteza/Code/instabot.py/src/instabot.py", line 569, in like
    like = self.s.post(url_likes)
  File "/home/morteza/anaconda3/lib/python3.6/site-packages/requests/sessions.py", line 535, in post
    return self.request('POST', url, data=data, json=json, **kwargs)
  File "/home/morteza/anaconda3/lib/python3.6/site-packages/requests/sessions.py", line 488, in request
    resp = self.send(prep, **send_kwargs)
  File "/home/morteza/anaconda3/lib/python3.6/site-packages/requests/sessions.py", line 609, in send
    r = adapter.send(request, **kwargs)
  File "/home/morteza/anaconda3/lib/python3.6/site-packages/requests/adapters.py", line 487, in send
    raise ConnectionError(e, request=request)
requests.exceptions.ConnectionError: HTTPSConnectionPool(host='www.instagram.com', port=443): Max retries exceeded with url: /web/likes/1704726188460920426/like/ (Caused by NewConnectionError('<requests.packages.urllib3.connection.VerifiedHTTPSConnection object at 0x7f65b0b00080>: Failed to establish a new connection: [Errno -2] Name or service not known',))
ERROR:root:get_media_id_by_tag
Traceback (most recent call last):
  File "/home/morteza/anaconda3/lib/python3.6/site-packages/requests/packages/urllib3/connection.py", line 141, in _new_conn
    (self.host, self.port), self.timeout, **extra_kw)
  File "/home/morteza/anaconda3/lib/python3.6/site-packages/requests/packages/urllib3/util/connection.py", line 60, in create_connection
    for res in socket.getaddrinfo(host, port, family, socket.SOCK_STREAM):
  File "/home/morteza/anaconda3/lib/python3.6/socket.py", line 743, in getaddrinfo
    for res in _socket.getaddrinfo(host, port, family, type, proto, flags):
socket.gaierror: [Errno -2] Name or service not known

During handling of the above exception, another exception occurred:

Traceback (most recent call last):
  File "/home/morteza/anaconda3/lib/python3.6/site-packages/requests/packages/urllib3/connectionpool.py", line 600, in urlopen
    chunked=chunked)
  File "/home/morteza/anaconda3/lib/python3.6/site-packages/requests/packages/urllib3/connectionpool.py", line 345, in _make_request
    self._validate_conn(conn)
  File "/home/morteza/anaconda3/lib/python3.6/site-packages/requests/packages/urllib3/connectionpool.py", line 844, in _validate_conn
    conn.connect()
  File "/home/morteza/anaconda3/lib/python3.6/site-packages/requests/packages/urllib3/connection.py", line 284, in connect
    conn = self._new_conn()
  File "/home/morteza/anaconda3/lib/python3.6/site-packages/requests/packages/urllib3/connection.py", line 150, in _new_conn
    self, "Failed to establish a new connection: %s" % e)
requests.packages.urllib3.exceptions.NewConnectionError: <requests.packages.urllib3.connection.VerifiedHTTPSConnection object at 0x7f65b0b002e8>: Failed to establish a new connection: [Errno -2] Name or service not known

During handling of the above exception, another exception occurred:

Traceback (most recent call last):
  File "/home/morteza/anaconda3/lib/python3.6/site-packages/requests/adapters.py", line 423, in send
    timeout=timeout
  File "/home/morteza/anaconda3/lib/python3.6/site-packages/requests/packages/urllib3/connectionpool.py", line 649, in urlopen
    _stacktrace=sys.exc_info()[2])
  File "/home/morteza/anaconda3/lib/python3.6/site-packages/requests/packages/urllib3/util/retry.py", line 376, in increment
    raise MaxRetryError(_pool, url, error or ResponseError(cause))
requests.packages.urllib3.exceptions.MaxRetryError: HTTPSConnectionPool(host='www.instagram.com', port=443): Max retries exceeded with url: /explore/tags/%D9%88%D8%B1%D8%B2%D8%B4/?__a=1 (Caused by NewConnectionError('<requests.packages.urllib3.connection.VerifiedHTTPSConnection object at 0x7f65b0b002e8>: Failed to establish a new connection: [Errno -2] Name or service not known',))

During handling of the above exception, another exception occurred:

Traceback (most recent call last):
  File "/home/morteza/Code/instabot.py/src/instabot.py", line 356, in get_media_id_by_tag
    r = self.s.get(url_tag)
  File "/home/morteza/anaconda3/lib/python3.6/site-packages/requests/sessions.py", line 501, in get
    return self.request('GET', url, **kwargs)
  File "/home/morteza/anaconda3/lib/python3.6/site-packages/requests/sessions.py", line 488, in request
    resp = self.send(prep, **send_kwargs)
  File "/home/morteza/anaconda3/lib/python3.6/site-packages/requests/sessions.py", line 609, in send
    r = adapter.send(request, **kwargs)
  File "/home/morteza/anaconda3/lib/python3.6/site-packages/requests/adapters.py", line 487, in send
    raise ConnectionError(e, request=request)
requests.exceptions.ConnectionError: HTTPSConnectionPool(host='www.instagram.com', port=443): Max retries exceeded with url: /explore/tags/%D9%88%D8%B1%D8%B2%D8%B4/?__a=1 (Caused by NewConnectionError('<requests.packages.urllib3.connection.VerifiedHTTPSConnection object at 0x7f65b0b002e8>: Failed to establish a new connection: [Errno -2] Name or service not known',))
ERROR:root:get_media_id_by_tag
Traceback (most recent call last):
  File "/home/morteza/anaconda3/lib/python3.6/site-packages/requests/packages/urllib3/connection.py", line 141, in _new_conn
    (self.host, self.port), self.timeout, **extra_kw)
  File "/home/morteza/anaconda3/lib/python3.6/site-packages/requests/packages/urllib3/util/connection.py", line 60, in create_connection
    for res in socket.getaddrinfo(host, port, family, socket.SOCK_STREAM):
  File "/home/morteza/anaconda3/lib/python3.6/socket.py", line 743, in getaddrinfo
    for res in _socket.getaddrinfo(host, port, family, type, proto, flags):
socket.gaierror: [Errno -2] Name or service not known

During handling of the above exception, another exception occurred:

Traceback (most recent call last):
  File "/home/morteza/anaconda3/lib/python3.6/site-packages/requests/packages/urllib3/connectionpool.py", line 600, in urlopen
    chunked=chunked)
  File "/home/morteza/anaconda3/lib/python3.6/site-packages/requests/packages/urllib3/connectionpool.py", line 345, in _make_request
    self._validate_conn(conn)
  File "/home/morteza/anaconda3/lib/python3.6/site-packages/requests/packages/urllib3/connectionpool.py", line 844, in _validate_conn
    conn.connect()
  File "/home/morteza/anaconda3/lib/python3.6/site-packages/requests/packages/urllib3/connection.py", line 284, in connect
    conn = self._new_conn()
  File "/home/morteza/anaconda3/lib/python3.6/site-packages/requests/packages/urllib3/connection.py", line 150, in _new_conn
    self, "Failed to establish a new connection: %s" % e)
requests.packages.urllib3.exceptions.NewConnectionError: <requests.packages.urllib3.connection.VerifiedHTTPSConnection object at 0x7f65b0b6bb70>: Failed to establish a new connection: [Errno -2] Name or service not known

During handling of the above exception, another exception occurred:

Traceback (most recent call last):
  File "/home/morteza/anaconda3/lib/python3.6/site-packages/requests/adapters.py", line 423, in send
    timeout=timeout
  File "/home/morteza/anaconda3/lib/python3.6/site-packages/requests/packages/urllib3/connectionpool.py", line 649, in urlopen
    _stacktrace=sys.exc_info()[2])
  File "/home/morteza/anaconda3/lib/python3.6/site-packages/requests/packages/urllib3/util/retry.py", line 376, in increment
    raise MaxRetryError(_pool, url, error or ResponseError(cause))
requests.packages.urllib3.exceptions.MaxRetryError: HTTPSConnectionPool(host='www.instagram.com', port=443): Max retries exceeded with url: /explore/tags/%D8%A8%D9%88%DA%A9%D8%B3/?__a=1 (Caused by NewConnectionError('<requests.packages.urllib3.connection.VerifiedHTTPSConnection object at 0x7f65b0b6bb70>: Failed to establish a new connection: [Errno -2] Name or service not known',))

During handling of the above exception, another exception occurred:

Traceback (most recent call last):
  File "/home/morteza/Code/instabot.py/src/instabot.py", line 356, in get_media_id_by_tag
    r = self.s.get(url_tag)
  File "/home/morteza/anaconda3/lib/python3.6/site-packages/requests/sessions.py", line 501, in get
    return self.request('GET', url, **kwargs)
  File "/home/morteza/anaconda3/lib/python3.6/site-packages/requests/sessions.py", line 488, in request
    resp = self.send(prep, **send_kwargs)
  File "/home/morteza/anaconda3/lib/python3.6/site-packages/requests/sessions.py", line 609, in send
    r = adapter.send(request, **kwargs)
  File "/home/morteza/anaconda3/lib/python3.6/site-packages/requests/adapters.py", line 487, in send
    raise ConnectionError(e, request=request)
requests.exceptions.ConnectionError: HTTPSConnectionPool(host='www.instagram.com', port=443): Max retries exceeded with url: /explore/tags/%D8%A8%D9%88%DA%A9%D8%B3/?__a=1 (Caused by NewConnectionError('<requests.packages.urllib3.connection.VerifiedHTTPSConnection object at 0x7f65b0b6bb70>: Failed to establish a new connection: [Errno -2] Name or service not known',))
ERROR:root:Except on auto_unfollow!
Traceback (most recent call last):
  File "/home/morteza/anaconda3/lib/python3.6/site-packages/requests/packages/urllib3/connection.py", line 141, in _new_conn
    (self.host, self.port), self.timeout, **extra_kw)
  File "/home/morteza/anaconda3/lib/python3.6/site-packages/requests/packages/urllib3/util/connection.py", line 60, in create_connection
    for res in socket.getaddrinfo(host, port, family, socket.SOCK_STREAM):
  File "/home/morteza/anaconda3/lib/python3.6/socket.py", line 743, in getaddrinfo
    for res in _socket.getaddrinfo(host, port, family, type, proto, flags):
socket.gaierror: [Errno -2] Name or service not known

During handling of the above exception, another exception occurred:

Traceback (most recent call last):
  File "/home/morteza/anaconda3/lib/python3.6/site-packages/requests/packages/urllib3/connectionpool.py", line 600, in urlopen
    chunked=chunked)
  File "/home/morteza/anaconda3/lib/python3.6/site-packages/requests/packages/urllib3/connectionpool.py", line 345, in _make_request
    self._validate_conn(conn)
  File "/home/morteza/anaconda3/lib/python3.6/site-packages/requests/packages/urllib3/connectionpool.py", line 844, in _validate_conn
    conn.connect()
  File "/home/morteza/anaconda3/lib/python3.6/site-packages/requests/packages/urllib3/connection.py", line 284, in connect
    conn = self._new_conn()
  File "/home/morteza/anaconda3/lib/python3.6/site-packages/requests/packages/urllib3/connection.py", line 150, in _new_conn
    self, "Failed to establish a new connection: %s" % e)
requests.packages.urllib3.exceptions.NewConnectionError: <requests.packages.urllib3.connection.VerifiedHTTPSConnection object at 0x7f65b0b00710>: Failed to establish a new connection: [Errno -2] Name or service not known

During handling of the above exception, another exception occurred:

Traceback (most recent call last):
  File "/home/morteza/anaconda3/lib/python3.6/site-packages/requests/adapters.py", line 423, in send
    timeout=timeout
  File "/home/morteza/anaconda3/lib/python3.6/site-packages/requests/packages/urllib3/connectionpool.py", line 649, in urlopen
    _stacktrace=sys.exc_info()[2])
  File "/home/morteza/anaconda3/lib/python3.6/site-packages/requests/packages/urllib3/util/retry.py", line 376, in increment
    raise MaxRetryError(_pool, url, error or ResponseError(cause))
requests.packages.urllib3.exceptions.MaxRetryError: HTTPSConnectionPool(host='www.instagram.com', port=443): Max retries exceeded with url: /bashgah_khonegi/?__a=1 (Caused by NewConnectionError('<requests.packages.urllib3.connection.VerifiedHTTPSConnection object at 0x7f65b0b00710>: Failed to establish a new connection: [Errno -2] Name or service not known',))

During handling of the above exception, another exception occurred:

Traceback (most recent call last):
  File "/home/morteza/Code/instabot.py/src/instabot.py", line 845, in auto_unfollow
    r = self.s.get(url_tag)
  File "/home/morteza/anaconda3/lib/python3.6/site-packages/requests/sessions.py", line 501, in get
    return self.request('GET', url, **kwargs)
  File "/home/morteza/anaconda3/lib/python3.6/site-packages/requests/sessions.py", line 488, in request
    resp = self.send(prep, **send_kwargs)
  File "/home/morteza/anaconda3/lib/python3.6/site-packages/requests/sessions.py", line 609, in send
    r = adapter.send(request, **kwargs)
  File "/home/morteza/anaconda3/lib/python3.6/site-packages/requests/adapters.py", line 487, in send
    raise ConnectionError(e, request=request)
requests.exceptions.ConnectionError: HTTPSConnectionPool(host='www.instagram.com', port=443): Max retries exceeded with url: /bashgah_khonegi/?__a=1 (Caused by NewConnectionError('<requests.packages.urllib3.connection.VerifiedHTTPSConnection object at 0x7f65b0b00710>: Failed to establish a new connection: [Errno -2] Name or service not known',))
ERROR:root:get_media_id_by_tag
Traceback (most recent call last):
  File "/home/morteza/anaconda3/lib/python3.6/site-packages/requests/packages/urllib3/connection.py", line 141, in _new_conn
    (self.host, self.port), self.timeout, **extra_kw)
  File "/home/morteza/anaconda3/lib/python3.6/site-packages/requests/packages/urllib3/util/connection.py", line 60, in create_connection
    for res in socket.getaddrinfo(host, port, family, socket.SOCK_STREAM):
  File "/home/morteza/anaconda3/lib/python3.6/socket.py", line 743, in getaddrinfo
    for res in _socket.getaddrinfo(host, port, family, type, proto, flags):
socket.gaierror: [Errno -2] Name or service not known

During handling of the above exception, another exception occurred:

Traceback (most recent call last):
  File "/home/morteza/anaconda3/lib/python3.6/site-packages/requests/packages/urllib3/connectionpool.py", line 600, in urlopen
    chunked=chunked)
  File "/home/morteza/anaconda3/lib/python3.6/site-packages/requests/packages/urllib3/connectionpool.py", line 345, in _make_request
    self._validate_conn(conn)
  File "/home/morteza/anaconda3/lib/python3.6/site-packages/requests/packages/urllib3/connectionpool.py", line 844, in _validate_conn
    conn.connect()
  File "/home/morteza/anaconda3/lib/python3.6/site-packages/requests/packages/urllib3/connection.py", line 284, in connect
    conn = self._new_conn()
  File "/home/morteza/anaconda3/lib/python3.6/site-packages/requests/packages/urllib3/connection.py", line 150, in _new_conn
    self, "Failed to establish a new connection: %s" % e)
requests.packages.urllib3.exceptions.NewConnectionError: <requests.packages.urllib3.connection.VerifiedHTTPSConnection object at 0x7f65b0b6b7f0>: Failed to establish a new connection: [Errno -2] Name or service not known

During handling of the above exception, another exception occurred:

Traceback (most recent call last):
  File "/home/morteza/anaconda3/lib/python3.6/site-packages/requests/adapters.py", line 423, in send
    timeout=timeout
  File "/home/morteza/anaconda3/lib/python3.6/site-packages/requests/packages/urllib3/connectionpool.py", line 649, in urlopen
    _stacktrace=sys.exc_info()[2])
  File "/home/morteza/anaconda3/lib/python3.6/site-packages/requests/packages/urllib3/util/retry.py", line 376, in increment
    raise MaxRetryError(_pool, url, error or ResponseError(cause))
requests.packages.urllib3.exceptions.MaxRetryError: HTTPSConnectionPool(host='www.instagram.com', port=443): Max retries exceeded with url: /explore/tags/%D8%AA%D9%85%D8%B1%DB%8C%D9%86/?__a=1 (Caused by NewConnectionError('<requests.packages.urllib3.connection.VerifiedHTTPSConnection object at 0x7f65b0b6b7f0>: Failed to establish a new connection: [Errno -2] Name or service not known',))

During handling of the above exception, another exception occurred:

Traceback (most recent call last):
  File "/home/morteza/Code/instabot.py/src/instabot.py", line 356, in get_media_id_by_tag
    r = self.s.get(url_tag)
  File "/home/morteza/anaconda3/lib/python3.6/site-packages/requests/sessions.py", line 501, in get
    return self.request('GET', url, **kwargs)
  File "/home/morteza/anaconda3/lib/python3.6/site-packages/requests/sessions.py", line 488, in request
    resp = self.send(prep, **send_kwargs)
  File "/home/morteza/anaconda3/lib/python3.6/site-packages/requests/sessions.py", line 609, in send
    r = adapter.send(request, **kwargs)
  File "/home/morteza/anaconda3/lib/python3.6/site-packages/requests/adapters.py", line 487, in send
    raise ConnectionError(e, request=request)
requests.exceptions.ConnectionError: HTTPSConnectionPool(host='www.instagram.com', port=443): Max retries exceeded with url: /explore/tags/%D8%AA%D9%85%D8%B1%DB%8C%D9%86/?__a=1 (Caused by NewConnectionError('<requests.packages.urllib3.connection.VerifiedHTTPSConnection object at 0x7f65b0b6b7f0>: Failed to establish a new connection: [Errno -2] Name or service not known',))
ERROR:root:get_media_id_by_tag
Traceback (most recent call last):
  File "/home/morteza/anaconda3/lib/python3.6/site-packages/requests/packages/urllib3/connection.py", line 141, in _new_conn
    (self.host, self.port), self.timeout, **extra_kw)
  File "/home/morteza/anaconda3/lib/python3.6/site-packages/requests/packages/urllib3/util/connection.py", line 60, in create_connection
    for res in socket.getaddrinfo(host, port, family, socket.SOCK_STREAM):
  File "/home/morteza/anaconda3/lib/python3.6/socket.py", line 743, in getaddrinfo
    for res in _socket.getaddrinfo(host, port, family, type, proto, flags):
socket.gaierror: [Errno -2] Name or service not known

During handling of the above exception, another exception occurred:

Traceback (most recent call last):
  File "/home/morteza/anaconda3/lib/python3.6/site-packages/requests/packages/urllib3/connectionpool.py", line 600, in urlopen
    chunked=chunked)
  File "/home/morteza/anaconda3/lib/python3.6/site-packages/requests/packages/urllib3/connectionpool.py", line 345, in _make_request
    self._validate_conn(conn)
  File "/home/morteza/anaconda3/lib/python3.6/site-packages/requests/packages/urllib3/connectionpool.py", line 844, in _validate_conn
    conn.connect()
  File "/home/morteza/anaconda3/lib/python3.6/site-packages/requests/packages/urllib3/connection.py", line 284, in connect
    conn = self._new_conn()
  File "/home/morteza/anaconda3/lib/python3.6/site-packages/requests/packages/urllib3/connection.py", line 150, in _new_conn
    self, "Failed to establish a new connection: %s" % e)
requests.packages.urllib3.exceptions.NewConnectionError: <requests.packages.urllib3.connection.VerifiedHTTPSConnection object at 0x7f65b0aebb70>: Failed to establish a new connection: [Errno -2] Name or service not known

During handling of the above exception, another exception occurred:

Traceback (most recent call last):
  File "/home/morteza/anaconda3/lib/python3.6/site-packages/requests/adapters.py", line 423, in send
    timeout=timeout
  File "/home/morteza/anaconda3/lib/python3.6/site-packages/requests/packages/urllib3/connectionpool.py", line 649, in urlopen
    _stacktrace=sys.exc_info()[2])
  File "/home/morteza/anaconda3/lib/python3.6/site-packages/requests/packages/urllib3/util/retry.py", line 376, in increment
    raise MaxRetryError(_pool, url, error or ResponseError(cause))
requests.packages.urllib3.exceptions.MaxRetryError: HTTPSConnectionPool(host='www.instagram.com', port=443): Max retries exceeded with url: /explore/tags/%D8%A8%D9%88%DA%A9%D8%B3/?__a=1 (Caused by NewConnectionError('<requests.packages.urllib3.connection.VerifiedHTTPSConnection object at 0x7f65b0aebb70>: Failed to establish a new connection: [Errno -2] Name or service not known',))

During handling of the above exception, another exception occurred:

Traceback (most recent call last):
  File "/home/morteza/Code/instabot.py/src/instabot.py", line 356, in get_media_id_by_tag
    r = self.s.get(url_tag)
  File "/home/morteza/anaconda3/lib/python3.6/site-packages/requests/sessions.py", line 501, in get
    return self.request('GET', url, **kwargs)
  File "/home/morteza/anaconda3/lib/python3.6/site-packages/requests/sessions.py", line 488, in request
    resp = self.send(prep, **send_kwargs)
  File "/home/morteza/anaconda3/lib/python3.6/site-packages/requests/sessions.py", line 609, in send
    r = adapter.send(request, **kwargs)
  File "/home/morteza/anaconda3/lib/python3.6/site-packages/requests/adapters.py", line 487, in send
    raise ConnectionError(e, request=request)
requests.exceptions.ConnectionError: HTTPSConnectionPool(host='www.instagram.com', port=443): Max retries exceeded with url: /explore/tags/%D8%A8%D9%88%DA%A9%D8%B3/?__a=1 (Caused by NewConnectionError('<requests.packages.urllib3.connection.VerifiedHTTPSConnection object at 0x7f65b0aebb70>: Failed to establish a new connection: [Errno -2] Name or service not known',))
ERROR:root:get_media_id_by_tag
Traceback (most recent call last):
  File "/home/morteza/anaconda3/lib/python3.6/site-packages/requests/packages/urllib3/connection.py", line 141, in _new_conn
    (self.host, self.port), self.timeout, **extra_kw)
  File "/home/morteza/anaconda3/lib/python3.6/site-packages/requests/packages/urllib3/util/connection.py", line 60, in create_connection
    for res in socket.getaddrinfo(host, port, family, socket.SOCK_STREAM):
  File "/home/morteza/anaconda3/lib/python3.6/socket.py", line 743, in getaddrinfo
    for res in _socket.getaddrinfo(host, port, family, type, proto, flags):
socket.gaierror: [Errno -2] Name or service not known

During handling of the above exception, another exception occurred:

Traceback (most recent call last):
  File "/home/morteza/anaconda3/lib/python3.6/site-packages/requests/packages/urllib3/connectionpool.py", line 600, in urlopen
    chunked=chunked)
  File "/home/morteza/anaconda3/lib/python3.6/site-packages/requests/packages/urllib3/connectionpool.py", line 345, in _make_request
    self._validate_conn(conn)
  File "/home/morteza/anaconda3/lib/python3.6/site-packages/requests/packages/urllib3/connectionpool.py", line 844, in _validate_conn
    conn.connect()
  File "/home/morteza/anaconda3/lib/python3.6/site-packages/requests/packages/urllib3/connection.py", line 284, in connect
    conn = self._new_conn()
  File "/home/morteza/anaconda3/lib/python3.6/site-packages/requests/packages/urllib3/connection.py", line 150, in _new_conn
    self, "Failed to establish a new connection: %s" % e)
requests.packages.urllib3.exceptions.NewConnectionError: <requests.packages.urllib3.connection.VerifiedHTTPSConnection object at 0x7f65b094cac8>: Failed to establish a new connection: [Errno -2] Name or service not known

During handling of the above exception, another exception occurred:

Traceback (most recent call last):
  File "/home/morteza/anaconda3/lib/python3.6/site-packages/requests/adapters.py", line 423, in send
    timeout=timeout
  File "/home/morteza/anaconda3/lib/python3.6/site-packages/requests/packages/urllib3/connectionpool.py", line 649, in urlopen
    _stacktrace=sys.exc_info()[2])
  File "/home/morteza/anaconda3/lib/python3.6/site-packages/requests/packages/urllib3/util/retry.py", line 376, in increment
    raise MaxRetryError(_pool, url, error or ResponseError(cause))
requests.packages.urllib3.exceptions.MaxRetryError: HTTPSConnectionPool(host='www.instagram.com', port=443): Max retries exceeded with url: /explore/tags/%D8%A8%D9%88%DA%A9%D8%B3/?__a=1 (Caused by NewConnectionError('<requests.packages.urllib3.connection.VerifiedHTTPSConnection object at 0x7f65b094cac8>: Failed to establish a new connection: [Errno -2] Name or service not known',))

During handling of the above exception, another exception occurred:

Traceback (most recent call last):
  File "/home/morteza/Code/instabot.py/src/instabot.py", line 356, in get_media_id_by_tag
    r = self.s.get(url_tag)
  File "/home/morteza/anaconda3/lib/python3.6/site-packages/requests/sessions.py", line 501, in get
    return self.request('GET', url, **kwargs)
  File "/home/morteza/anaconda3/lib/python3.6/site-packages/requests/sessions.py", line 488, in request
    resp = self.send(prep, **send_kwargs)
  File "/home/morteza/anaconda3/lib/python3.6/site-packages/requests/sessions.py", line 609, in send
    r = adapter.send(request, **kwargs)
  File "/home/morteza/anaconda3/lib/python3.6/site-packages/requests/adapters.py", line 487, in send
    raise ConnectionError(e, request=request)
requests.exceptions.ConnectionError: HTTPSConnectionPool(host='www.instagram.com', port=443): Max retries exceeded with url: /explore/tags/%D8%A8%D9%88%DA%A9%D8%B3/?__a=1 (Caused by NewConnectionError('<requests.packages.urllib3.connection.VerifiedHTTPSConnection object at 0x7f65b094cac8>: Failed to establish a new connection: [Errno -2] Name or service not known',))
ERROR:root:get_media_id_by_tag
Traceback (most recent call last):
  File "/home/morteza/anaconda3/lib/python3.6/site-packages/requests/packages/urllib3/connection.py", line 141, in _new_conn
    (self.host, self.port), self.timeout, **extra_kw)
  File "/home/morteza/anaconda3/lib/python3.6/site-packages/requests/packages/urllib3/util/connection.py", line 60, in create_connection
    for res in socket.getaddrinfo(host, port, family, socket.SOCK_STREAM):
  File "/home/morteza/anaconda3/lib/python3.6/socket.py", line 743, in getaddrinfo
    for res in _socket.getaddrinfo(host, port, family, type, proto, flags):
socket.gaierror: [Errno -2] Name or service not known

During handling of the above exception, another exception occurred:

Traceback (most recent call last):
  File "/home/morteza/anaconda3/lib/python3.6/site-packages/requests/packages/urllib3/connectionpool.py", line 600, in urlopen
    chunked=chunked)
  File "/home/morteza/anaconda3/lib/python3.6/site-packages/requests/packages/urllib3/connectionpool.py", line 345, in _make_request
    self._validate_conn(conn)
  File "/home/morteza/anaconda3/lib/python3.6/site-packages/requests/packages/urllib3/connectionpool.py", line 844, in _validate_conn
    conn.connect()
  File "/home/morteza/anaconda3/lib/python3.6/site-packages/requests/packages/urllib3/connection.py", line 284, in connect
    conn = self._new_conn()
  File "/home/morteza/anaconda3/lib/python3.6/site-packages/requests/packages/urllib3/connection.py", line 150, in _new_conn
    self, "Failed to establish a new connection: %s" % e)
requests.packages.urllib3.exceptions.NewConnectionError: <requests.packages.urllib3.connection.VerifiedHTTPSConnection object at 0x7f65b0aeab38>: Failed to establish a new connection: [Errno -2] Name or service not known

During handling of the above exception, another exception occurred:

Traceback (most recent call last):
  File "/home/morteza/anaconda3/lib/python3.6/site-packages/requests/adapters.py", line 423, in send
    timeout=timeout
  File "/home/morteza/anaconda3/lib/python3.6/site-packages/requests/packages/urllib3/connectionpool.py", line 649, in urlopen
    _stacktrace=sys.exc_info()[2])
  File "/home/morteza/anaconda3/lib/python3.6/site-packages/requests/packages/urllib3/util/retry.py", line 376, in increment
    raise MaxRetryError(_pool, url, error or ResponseError(cause))
requests.packages.urllib3.exceptions.MaxRetryError: HTTPSConnectionPool(host='www.instagram.com', port=443): Max retries exceeded with url: /explore/tags/%D9%88%D8%B1%D8%B2%D8%B4/?__a=1 (Caused by NewConnectionError('<requests.packages.urllib3.connection.VerifiedHTTPSConnection object at 0x7f65b0aeab38>: Failed to establish a new connection: [Errno -2] Name or service not known',))

During handling of the above exception, another exception occurred:

Traceback (most recent call last):
  File "/home/morteza/Code/instabot.py/src/instabot.py", line 356, in get_media_id_by_tag
    r = self.s.get(url_tag)
  File "/home/morteza/anaconda3/lib/python3.6/site-packages/requests/sessions.py", line 501, in get
    return self.request('GET', url, **kwargs)
  File "/home/morteza/anaconda3/lib/python3.6/site-packages/requests/sessions.py", line 488, in request
    resp = self.send(prep, **send_kwargs)
  File "/home/morteza/anaconda3/lib/python3.6/site-packages/requests/sessions.py", line 609, in send
    r = adapter.send(request, **kwargs)
  File "/home/morteza/anaconda3/lib/python3.6/site-packages/requests/adapters.py", line 487, in send
    raise ConnectionError(e, request=request)
requests.exceptions.ConnectionError: HTTPSConnectionPool(host='www.instagram.com', port=443): Max retries exceeded with url: /explore/tags/%D9%88%D8%B1%D8%B2%D8%B4/?__a=1 (Caused by NewConnectionError('<requests.packages.urllib3.connection.VerifiedHTTPSConnection object at 0x7f65b0aeab38>: Failed to establish a new connection: [Errno -2] Name or service not known',))
ERROR:root:Except on get_username_by_user_id
Traceback (most recent call last):
  File "/home/morteza/anaconda3/lib/python3.6/site-packages/requests/packages/urllib3/connection.py", line 141, in _new_conn
    (self.host, self.port), self.timeout, **extra_kw)
  File "/home/morteza/anaconda3/lib/python3.6/site-packages/requests/packages/urllib3/util/connection.py", line 60, in create_connection
    for res in socket.getaddrinfo(host, port, family, socket.SOCK_STREAM):
  File "/home/morteza/anaconda3/lib/python3.6/socket.py", line 743, in getaddrinfo
    for res in _socket.getaddrinfo(host, port, family, type, proto, flags):
socket.gaierror: [Errno -2] Name or service not known

During handling of the above exception, another exception occurred:

Traceback (most recent call last):
  File "/home/morteza/anaconda3/lib/python3.6/site-packages/requests/packages/urllib3/connectionpool.py", line 600, in urlopen
    chunked=chunked)
  File "/home/morteza/anaconda3/lib/python3.6/site-packages/requests/packages/urllib3/connectionpool.py", line 345, in _make_request
    self._validate_conn(conn)
  File "/home/morteza/anaconda3/lib/python3.6/site-packages/requests/packages/urllib3/connectionpool.py", line 844, in _validate_conn
    conn.connect()
  File "/home/morteza/anaconda3/lib/python3.6/site-packages/requests/packages/urllib3/connection.py", line 284, in connect
    conn = self._new_conn()
  File "/home/morteza/anaconda3/lib/python3.6/site-packages/requests/packages/urllib3/connection.py", line 150, in _new_conn
    self, "Failed to establish a new connection: %s" % e)
requests.packages.urllib3.exceptions.NewConnectionError: <requests.packages.urllib3.connection.VerifiedHTTPSConnection object at 0x7f65b0b27400>: Failed to establish a new connection: [Errno -2] Name or service not known

During handling of the above exception, another exception occurred:

Traceback (most recent call last):
  File "/home/morteza/anaconda3/lib/python3.6/site-packages/requests/adapters.py", line 423, in send
    timeout=timeout
  File "/home/morteza/anaconda3/lib/python3.6/site-packages/requests/packages/urllib3/connectionpool.py", line 649, in urlopen
    _stacktrace=sys.exc_info()[2])
  File "/home/morteza/anaconda3/lib/python3.6/site-packages/requests/packages/urllib3/util/retry.py", line 376, in increment
    raise MaxRetryError(_pool, url, error or ResponseError(cause))
requests.packages.urllib3.exceptions.MaxRetryError: HTTPSConnectionPool(host='i.instagram.com', port=443): Max retries exceeded with url: /api/v1/users/3020527655/info/ (Caused by NewConnectionError('<requests.packages.urllib3.connection.VerifiedHTTPSConnection object at 0x7f65b0b27400>: Failed to establish a new connection: [Errno -2] Name or service not known',))

During handling of the above exception, another exception occurred:

Traceback (most recent call last):
  File "/home/morteza/Code/instabot.py/src/instabot.py", line 405, in get_username_by_user_id
    r = self.s.get(url_info, headers="")
  File "/home/morteza/anaconda3/lib/python3.6/site-packages/requests/sessions.py", line 501, in get
    return self.request('GET', url, **kwargs)
  File "/home/morteza/anaconda3/lib/python3.6/site-packages/requests/sessions.py", line 488, in request
    resp = self.send(prep, **send_kwargs)
  File "/home/morteza/anaconda3/lib/python3.6/site-packages/requests/sessions.py", line 609, in send
    r = adapter.send(request, **kwargs)
  File "/home/morteza/anaconda3/lib/python3.6/site-packages/requests/adapters.py", line 487, in send
    raise ConnectionError(e, request=request)
requests.exceptions.ConnectionError: HTTPSConnectionPool(host='i.instagram.com', port=443): Max retries exceeded with url: /api/v1/users/3020527655/info/ (Caused by NewConnectionError('<requests.packages.urllib3.connection.VerifiedHTTPSConnection object at 0x7f65b0b27400>: Failed to establish a new connection: [Errno -2] Name or service not known',))
ERROR:root:Except on follow!
Traceback (most recent call last):
  File "/home/morteza/Code/instabot.py/src/instabot.py", line 616, in follow
    insert_username(self, user_id=user_id, username=username)
  File "/home/morteza/Code/instabot.py/src/sql_updates.py", line 74, in insert_username
    VALUES('"+user_id+"','"+username+"','"+ str(now) +"')")
TypeError: must be str, not bool
ERROR:root:get_media_id_by_tag
Traceback (most recent call last):
  File "/home/morteza/Code/instabot.py/src/instabot.py", line 357, in get_media_id_by_tag
    all_data = json.loads(r.text)
  File "/home/morteza/anaconda3/lib/python3.6/json/__init__.py", line 354, in loads
    return _default_decoder.decode(s)
  File "/home/morteza/anaconda3/lib/python3.6/json/decoder.py", line 339, in decode
    obj, end = self.raw_decode(s, idx=_w(s, 0).end())
  File "/home/morteza/anaconda3/lib/python3.6/json/decoder.py", line 357, in raw_decode
    raise JSONDecodeError("Expecting value", s, err.value) from None
json.decoder.JSONDecodeError: Expecting value: line 1 column 1 (char 0)
ERROR:root:Except on follow!
Traceback (most recent call last):
  File "/home/morteza/anaconda3/lib/python3.6/site-packages/requests/packages/urllib3/connection.py", line 141, in _new_conn
    (self.host, self.port), self.timeout, **extra_kw)
  File "/home/morteza/anaconda3/lib/python3.6/site-packages/requests/packages/urllib3/util/connection.py", line 60, in create_connection
    for res in socket.getaddrinfo(host, port, family, socket.SOCK_STREAM):
  File "/home/morteza/anaconda3/lib/python3.6/socket.py", line 743, in getaddrinfo
    for res in _socket.getaddrinfo(host, port, family, type, proto, flags):
socket.gaierror: [Errno -2] Name or service not known

During handling of the above exception, another exception occurred:

Traceback (most recent call last):
  File "/home/morteza/anaconda3/lib/python3.6/site-packages/requests/packages/urllib3/connectionpool.py", line 600, in urlopen
    chunked=chunked)
  File "/home/morteza/anaconda3/lib/python3.6/site-packages/requests/packages/urllib3/connectionpool.py", line 345, in _make_request
    self._validate_conn(conn)
  File "/home/morteza/anaconda3/lib/python3.6/site-packages/requests/packages/urllib3/connectionpool.py", line 844, in _validate_conn
    conn.connect()
  File "/home/morteza/anaconda3/lib/python3.6/site-packages/requests/packages/urllib3/connection.py", line 284, in connect
    conn = self._new_conn()
  File "/home/morteza/anaconda3/lib/python3.6/site-packages/requests/packages/urllib3/connection.py", line 150, in _new_conn
    self, "Failed to establish a new connection: %s" % e)
requests.packages.urllib3.exceptions.NewConnectionError: <requests.packages.urllib3.connection.VerifiedHTTPSConnection object at 0x7f65b0b00710>: Failed to establish a new connection: [Errno -2] Name or service not known

During handling of the above exception, another exception occurred:

Traceback (most recent call last):
  File "/home/morteza/anaconda3/lib/python3.6/site-packages/requests/adapters.py", line 423, in send
    timeout=timeout
  File "/home/morteza/anaconda3/lib/python3.6/site-packages/requests/packages/urllib3/connectionpool.py", line 649, in urlopen
    _stacktrace=sys.exc_info()[2])
  File "/home/morteza/anaconda3/lib/python3.6/site-packages/requests/packages/urllib3/util/retry.py", line 376, in increment
    raise MaxRetryError(_pool, url, error or ResponseError(cause))
requests.packages.urllib3.exceptions.MaxRetryError: HTTPSConnectionPool(host='www.instagram.com', port=443): Max retries exceeded with url: /web/friendships/5636123965/follow/ (Caused by NewConnectionError('<requests.packages.urllib3.connection.VerifiedHTTPSConnection object at 0x7f65b0b00710>: Failed to establish a new connection: [Errno -2] Name or service not known',))

During handling of the above exception, another exception occurred:

Traceback (most recent call last):
  File "/home/morteza/Code/instabot.py/src/instabot.py", line 609, in follow
    follow = self.s.post(url_follow)
  File "/home/morteza/anaconda3/lib/python3.6/site-packages/requests/sessions.py", line 535, in post
    return self.request('POST', url, data=data, json=json, **kwargs)
  File "/home/morteza/anaconda3/lib/python3.6/site-packages/requests/sessions.py", line 488, in request
    resp = self.send(prep, **send_kwargs)
  File "/home/morteza/anaconda3/lib/python3.6/site-packages/requests/sessions.py", line 609, in send
    r = adapter.send(request, **kwargs)
  File "/home/morteza/anaconda3/lib/python3.6/site-packages/requests/adapters.py", line 487, in send
    raise ConnectionError(e, request=request)
requests.exceptions.ConnectionError: HTTPSConnectionPool(host='www.instagram.com', port=443): Max retries exceeded with url: /web/friendships/5636123965/follow/ (Caused by NewConnectionError('<requests.packages.urllib3.connection.VerifiedHTTPSConnection object at 0x7f65b0b00710>: Failed to establish a new connection: [Errno -2] Name or service not known',))
ERROR:root:Except on unfollow... Looks like a network error
Traceback (most recent call last):
  File "/home/morteza/Code/instabot.py/src/instabot.py", line 643, in unfollow_on_cleanup
    unfollow = self.s.post(url_unfollow)
  File "/home/morteza/anaconda3/lib/python3.6/site-packages/requests/sessions.py", line 535, in post
    return self.request('POST', url, data=data, json=json, **kwargs)
  File "/home/morteza/anaconda3/lib/python3.6/site-packages/requests/sessions.py", line 488, in request
    resp = self.send(prep, **send_kwargs)
  File "/home/morteza/anaconda3/lib/python3.6/site-packages/requests/sessions.py", line 609, in send
    r = adapter.send(request, **kwargs)
  File "/home/morteza/anaconda3/lib/python3.6/site-packages/requests/adapters.py", line 423, in send
    timeout=timeout
  File "/home/morteza/anaconda3/lib/python3.6/site-packages/requests/packages/urllib3/connectionpool.py", line 600, in urlopen
    chunked=chunked)
  File "/home/morteza/anaconda3/lib/python3.6/site-packages/requests/packages/urllib3/connectionpool.py", line 345, in _make_request
    self._validate_conn(conn)
  File "/home/morteza/anaconda3/lib/python3.6/site-packages/requests/packages/urllib3/connectionpool.py", line 844, in _validate_conn
    conn.connect()
  File "/home/morteza/anaconda3/lib/python3.6/site-packages/requests/packages/urllib3/connection.py", line 284, in connect
    conn = self._new_conn()
  File "/home/morteza/anaconda3/lib/python3.6/site-packages/requests/packages/urllib3/connection.py", line 141, in _new_conn
    (self.host, self.port), self.timeout, **extra_kw)
  File "/home/morteza/anaconda3/lib/python3.6/site-packages/requests/packages/urllib3/util/connection.py", line 60, in create_connection
    for res in socket.getaddrinfo(host, port, family, socket.SOCK_STREAM):
  File "/home/morteza/anaconda3/lib/python3.6/socket.py", line 743, in getaddrinfo
    for res in _socket.getaddrinfo(host, port, family, type, proto, flags):
KeyboardInterrupt
ERROR:root:Except on unfollow... Looks like a network error
Traceback (most recent call last):
  File "/home/morteza/anaconda3/lib/python3.6/site-packages/requests/packages/urllib3/connectionpool.py", line 379, in _make_request
    httplib_response = conn.getresponse(buffering=True)
TypeError: getresponse() got an unexpected keyword argument 'buffering'

During handling of the above exception, another exception occurred:

Traceback (most recent call last):
  File "/home/morteza/Code/instabot.py/src/instabot.py", line 643, in unfollow_on_cleanup
    unfollow = self.s.post(url_unfollow)
  File "/home/morteza/anaconda3/lib/python3.6/site-packages/requests/sessions.py", line 535, in post
    return self.request('POST', url, data=data, json=json, **kwargs)
  File "/home/morteza/anaconda3/lib/python3.6/site-packages/requests/sessions.py", line 488, in request
    resp = self.send(prep, **send_kwargs)
  File "/home/morteza/anaconda3/lib/python3.6/site-packages/requests/sessions.py", line 609, in send
    r = adapter.send(request, **kwargs)
  File "/home/morteza/anaconda3/lib/python3.6/site-packages/requests/adapters.py", line 423, in send
    timeout=timeout
  File "/home/morteza/anaconda3/lib/python3.6/site-packages/requests/packages/urllib3/connectionpool.py", line 600, in urlopen
    chunked=chunked)
  File "/home/morteza/anaconda3/lib/python3.6/site-packages/requests/packages/urllib3/connectionpool.py", line 382, in _make_request
    httplib_response = conn.getresponse()
  File "/home/morteza/anaconda3/lib/python3.6/http/client.py", line 1331, in getresponse
    response.begin()
  File "/home/morteza/anaconda3/lib/python3.6/http/client.py", line 297, in begin
    version, status, reason = self._read_status()
  File "/home/morteza/anaconda3/lib/python3.6/http/client.py", line 258, in _read_status
    line = str(self.fp.readline(_MAXLINE + 1), "iso-8859-1")
  File "/home/morteza/anaconda3/lib/python3.6/socket.py", line 586, in readinto
    return self._sock.recv_into(b)
  File "/home/morteza/anaconda3/lib/python3.6/site-packages/requests/packages/urllib3/contrib/pyopenssl.py", line 277, in recv_into
    return self.connection.recv_into(*args, **kwargs)
  File "/home/morteza/anaconda3/lib/python3.6/site-packages/OpenSSL/SSL.py", line 1546, in recv_into
    result = _lib.SSL_read(self._ssl, buf, nbytes)
KeyboardInterrupt
ERROR:root:Except on unfollow... Looks like a network error
Traceback (most recent call last):
  File "/home/morteza/Code/instabot.py/src/instabot.py", line 643, in unfollow_on_cleanup
    unfollow = self.s.post(url_unfollow)
  File "/home/morteza/anaconda3/lib/python3.6/site-packages/requests/sessions.py", line 535, in post
    return self.request('POST', url, data=data, json=json, **kwargs)
  File "/home/morteza/anaconda3/lib/python3.6/site-packages/requests/sessions.py", line 488, in request
    resp = self.send(prep, **send_kwargs)
  File "/home/morteza/anaconda3/lib/python3.6/site-packages/requests/sessions.py", line 609, in send
    r = adapter.send(request, **kwargs)
  File "/home/morteza/anaconda3/lib/python3.6/site-packages/requests/adapters.py", line 423, in send
    timeout=timeout
  File "/home/morteza/anaconda3/lib/python3.6/site-packages/requests/packages/urllib3/connectionpool.py", line 600, in urlopen
    chunked=chunked)
  File "/home/morteza/anaconda3/lib/python3.6/site-packages/requests/packages/urllib3/connectionpool.py", line 345, in _make_request
    self._validate_conn(conn)
  File "/home/morteza/anaconda3/lib/python3.6/site-packages/requests/packages/urllib3/connectionpool.py", line 844, in _validate_conn
    conn.connect()
  File "/home/morteza/anaconda3/lib/python3.6/site-packages/requests/packages/urllib3/connection.py", line 284, in connect
    conn = self._new_conn()
  File "/home/morteza/anaconda3/lib/python3.6/site-packages/requests/packages/urllib3/connection.py", line 141, in _new_conn
    (self.host, self.port), self.timeout, **extra_kw)
  File "/home/morteza/anaconda3/lib/python3.6/site-packages/requests/packages/urllib3/util/connection.py", line 60, in create_connection
    for res in socket.getaddrinfo(host, port, family, socket.SOCK_STREAM):
  File "/home/morteza/anaconda3/lib/python3.6/socket.py", line 743, in getaddrinfo
    for res in _socket.getaddrinfo(host, port, family, type, proto, flags):
KeyboardInterrupt
WARNING:fake_useragent:Error occurred during loading data. Trying to use cache server http://d2g6u4gh6d9rq0.cloudfront.net/browsers/fake_useragent_0.1.10.json
Traceback (most recent call last):
  File "/usr/lib/python3.5/urllib/request.py", line 1254, in do_open
    h.request(req.get_method(), req.selector, req.data, headers)
  File "/usr/lib/python3.5/http/client.py", line 1106, in request
    self._send_request(method, url, body, headers)
  File "/usr/lib/python3.5/http/client.py", line 1151, in _send_request
    self.endheaders(body)
  File "/usr/lib/python3.5/http/client.py", line 1102, in endheaders
    self._send_output(message_body)
  File "/usr/lib/python3.5/http/client.py", line 934, in _send_output
    self.send(msg)
  File "/usr/lib/python3.5/http/client.py", line 877, in send
    self.connect()
  File "/usr/lib/python3.5/http/client.py", line 1260, in connect
    server_hostname=server_hostname)
  File "/usr/lib/python3.5/ssl.py", line 377, in wrap_socket
    _context=self)
  File "/usr/lib/python3.5/ssl.py", line 752, in __init__
    self.do_handshake()
  File "/usr/lib/python3.5/ssl.py", line 988, in do_handshake
    self._sslobj.do_handshake()
  File "/usr/lib/python3.5/ssl.py", line 633, in do_handshake
    self._sslobj.do_handshake()
socket.timeout: _ssl.c:629: The handshake operation timed out

During handling of the above exception, another exception occurred:

Traceback (most recent call last):
  File "/home/morteza/venvs/instapy/lib/python3.5/site-packages/fake_useragent/utils.py", line 67, in get
    context=context,
  File "/usr/lib/python3.5/urllib/request.py", line 163, in urlopen
    return opener.open(url, data, timeout)
  File "/usr/lib/python3.5/urllib/request.py", line 466, in open
    response = self._open(req, data)
  File "/usr/lib/python3.5/urllib/request.py", line 484, in _open
    '_open', req)
  File "/usr/lib/python3.5/urllib/request.py", line 444, in _call_chain
    result = func(*args)
  File "/usr/lib/python3.5/urllib/request.py", line 1297, in https_open
    context=self._context, check_hostname=self._check_hostname)
  File "/usr/lib/python3.5/urllib/request.py", line 1256, in do_open
    raise URLError(err)
urllib.error.URLError: <urlopen error _ssl.c:629: The handshake operation timed out>

During handling of the above exception, another exception occurred:

Traceback (most recent call last):
  File "/home/morteza/venvs/instapy/lib/python3.5/site-packages/fake_useragent/utils.py", line 154, in load
    for item in get_browsers(verify_ssl=verify_ssl):
  File "/home/morteza/venvs/instapy/lib/python3.5/site-packages/fake_useragent/utils.py", line 97, in get_browsers
    html = get(settings.BROWSERS_STATS_PAGE, verify_ssl=verify_ssl)
  File "/home/morteza/venvs/instapy/lib/python3.5/site-packages/fake_useragent/utils.py", line 84, in get
    raise FakeUserAgentError('Maximum amount of retries reached')
fake_useragent.errors.FakeUserAgentError: Maximum amount of retries reached
ERROR:root:Except on unfollow... Looks like a network error
Traceback (most recent call last):
  File "/home/morteza/Code/instabot.py/src/instabot.py", line 643, in unfollow_on_cleanup
    unfollow = self.s.post(url_unfollow)
  File "/home/morteza/venvs/instapy/lib/python3.5/site-packages/requests/sessions.py", line 535, in post
    return self.request('POST', url, data=data, json=json, **kwargs)
  File "/home/morteza/venvs/instapy/lib/python3.5/site-packages/requests/sessions.py", line 488, in request
    resp = self.send(prep, **send_kwargs)
  File "/home/morteza/venvs/instapy/lib/python3.5/site-packages/requests/sessions.py", line 609, in send
    r = adapter.send(request, **kwargs)
  File "/home/morteza/venvs/instapy/lib/python3.5/site-packages/requests/adapters.py", line 423, in send
    timeout=timeout
  File "/home/morteza/venvs/instapy/lib/python3.5/site-packages/requests/packages/urllib3/connectionpool.py", line 600, in urlopen
    chunked=chunked)
  File "/home/morteza/venvs/instapy/lib/python3.5/site-packages/requests/packages/urllib3/connectionpool.py", line 345, in _make_request
    self._validate_conn(conn)
  File "/home/morteza/venvs/instapy/lib/python3.5/site-packages/requests/packages/urllib3/connectionpool.py", line 844, in _validate_conn
    conn.connect()
  File "/home/morteza/venvs/instapy/lib/python3.5/site-packages/requests/packages/urllib3/connection.py", line 284, in connect
    conn = self._new_conn()
  File "/home/morteza/venvs/instapy/lib/python3.5/site-packages/requests/packages/urllib3/connection.py", line 141, in _new_conn
    (self.host, self.port), self.timeout, **extra_kw)
  File "/home/morteza/venvs/instapy/lib/python3.5/site-packages/requests/packages/urllib3/util/connection.py", line 73, in create_connection
    sock.connect(sa)
KeyboardInterrupt
ERROR:root:Except on auto_unfollow!
Traceback (most recent call last):
  File "/home/morteza/Code/instagram_bot/bot/src/instabot.py", line 846, in auto_unfollow
    all_data = json.loads(r.text)
  File "/usr/lib/python3.5/json/__init__.py", line 319, in loads
    return _default_decoder.decode(s)
  File "/usr/lib/python3.5/json/decoder.py", line 339, in decode
    obj, end = self.raw_decode(s, idx=_w(s, 0).end())
  File "/usr/lib/python3.5/json/decoder.py", line 357, in raw_decode
    raise JSONDecodeError("Expecting value", s, err.value) from None
json.decoder.JSONDecodeError: Expecting value: line 1 column 1 (char 0)
ERROR:root:Except on unfollow... Looks like a network error
Traceback (most recent call last):
  File "/home/morteza/venvs/instapy/lib/python3.5/site-packages/requests/packages/urllib3/connectionpool.py", line 379, in _make_request
    httplib_response = conn.getresponse(buffering=True)
TypeError: getresponse() got an unexpected keyword argument 'buffering'

During handling of the above exception, another exception occurred:

Traceback (most recent call last):
  File "/home/morteza/Code/instagram_bot/bot/src/instabot.py", line 643, in unfollow_on_cleanup
    unfollow = self.s.post(url_unfollow)
  File "/home/morteza/venvs/instapy/lib/python3.5/site-packages/requests/sessions.py", line 535, in post
    return self.request('POST', url, data=data, json=json, **kwargs)
  File "/home/morteza/venvs/instapy/lib/python3.5/site-packages/requests/sessions.py", line 488, in request
    resp = self.send(prep, **send_kwargs)
  File "/home/morteza/venvs/instapy/lib/python3.5/site-packages/requests/sessions.py", line 609, in send
    r = adapter.send(request, **kwargs)
  File "/home/morteza/venvs/instapy/lib/python3.5/site-packages/requests/adapters.py", line 423, in send
    timeout=timeout
  File "/home/morteza/venvs/instapy/lib/python3.5/site-packages/requests/packages/urllib3/connectionpool.py", line 600, in urlopen
    chunked=chunked)
  File "/home/morteza/venvs/instapy/lib/python3.5/site-packages/requests/packages/urllib3/connectionpool.py", line 382, in _make_request
    httplib_response = conn.getresponse()
  File "/usr/lib/python3.5/http/client.py", line 1197, in getresponse
    response.begin()
  File "/usr/lib/python3.5/http/client.py", line 297, in begin
    version, status, reason = self._read_status()
  File "/usr/lib/python3.5/http/client.py", line 258, in _read_status
    line = str(self.fp.readline(_MAXLINE + 1), "iso-8859-1")
  File "/usr/lib/python3.5/socket.py", line 575, in readinto
    return self._sock.recv_into(b)
  File "/usr/lib/python3.5/ssl.py", line 929, in recv_into
    return self.read(nbytes, buffer)
  File "/usr/lib/python3.5/ssl.py", line 791, in read
    return self._sslobj.read(len, buffer)
  File "/usr/lib/python3.5/ssl.py", line 575, in read
    v = self._sslobj.read(len, buffer)
KeyboardInterrupt
ERROR:root:Except on unfollow... Looks like a network error
Traceback (most recent call last):
  File "/home/morteza/venvs/instapy/lib/python3.5/site-packages/requests/packages/urllib3/connectionpool.py", line 379, in _make_request
    httplib_response = conn.getresponse(buffering=True)
TypeError: getresponse() got an unexpected keyword argument 'buffering'

During handling of the above exception, another exception occurred:

Traceback (most recent call last):
  File "/home/morteza/Code/instagram_bot/bot/src/instabot.py", line 643, in unfollow_on_cleanup
    unfollow = self.s.post(url_unfollow)
  File "/home/morteza/venvs/instapy/lib/python3.5/site-packages/requests/sessions.py", line 535, in post
    return self.request('POST', url, data=data, json=json, **kwargs)
  File "/home/morteza/venvs/instapy/lib/python3.5/site-packages/requests/sessions.py", line 488, in request
    resp = self.send(prep, **send_kwargs)
  File "/home/morteza/venvs/instapy/lib/python3.5/site-packages/requests/sessions.py", line 609, in send
    r = adapter.send(request, **kwargs)
  File "/home/morteza/venvs/instapy/lib/python3.5/site-packages/requests/adapters.py", line 423, in send
    timeout=timeout
  File "/home/morteza/venvs/instapy/lib/python3.5/site-packages/requests/packages/urllib3/connectionpool.py", line 600, in urlopen
    chunked=chunked)
  File "/home/morteza/venvs/instapy/lib/python3.5/site-packages/requests/packages/urllib3/connectionpool.py", line 382, in _make_request
    httplib_response = conn.getresponse()
  File "/usr/lib/python3.5/http/client.py", line 1197, in getresponse
    response.begin()
  File "/usr/lib/python3.5/http/client.py", line 297, in begin
    version, status, reason = self._read_status()
  File "/usr/lib/python3.5/http/client.py", line 258, in _read_status
    line = str(self.fp.readline(_MAXLINE + 1), "iso-8859-1")
  File "/usr/lib/python3.5/socket.py", line 575, in readinto
    return self._sock.recv_into(b)
  File "/usr/lib/python3.5/ssl.py", line 929, in recv_into
    return self.read(nbytes, buffer)
  File "/usr/lib/python3.5/ssl.py", line 791, in read
    return self._sslobj.read(len, buffer)
  File "/usr/lib/python3.5/ssl.py", line 575, in read
    v = self._sslobj.read(len, buffer)
KeyboardInterrupt
ERROR:root:Except on unfollow... Looks like a network error
Traceback (most recent call last):
  File "/home/morteza/venvs/instapy/lib/python3.5/site-packages/requests/packages/urllib3/connectionpool.py", line 379, in _make_request
    httplib_response = conn.getresponse(buffering=True)
TypeError: getresponse() got an unexpected keyword argument 'buffering'

During handling of the above exception, another exception occurred:

Traceback (most recent call last):
  File "/home/morteza/Code/instagram_bot/bot/src/instabot.py", line 643, in unfollow_on_cleanup
    unfollow = self.s.post(url_unfollow)
  File "/home/morteza/venvs/instapy/lib/python3.5/site-packages/requests/sessions.py", line 535, in post
    return self.request('POST', url, data=data, json=json, **kwargs)
  File "/home/morteza/venvs/instapy/lib/python3.5/site-packages/requests/sessions.py", line 488, in request
    resp = self.send(prep, **send_kwargs)
  File "/home/morteza/venvs/instapy/lib/python3.5/site-packages/requests/sessions.py", line 609, in send
    r = adapter.send(request, **kwargs)
  File "/home/morteza/venvs/instapy/lib/python3.5/site-packages/requests/adapters.py", line 423, in send
    timeout=timeout
  File "/home/morteza/venvs/instapy/lib/python3.5/site-packages/requests/packages/urllib3/connectionpool.py", line 600, in urlopen
    chunked=chunked)
  File "/home/morteza/venvs/instapy/lib/python3.5/site-packages/requests/packages/urllib3/connectionpool.py", line 382, in _make_request
    httplib_response = conn.getresponse()
  File "/usr/lib/python3.5/http/client.py", line 1197, in getresponse
    response.begin()
  File "/usr/lib/python3.5/http/client.py", line 297, in begin
    version, status, reason = self._read_status()
  File "/usr/lib/python3.5/http/client.py", line 258, in _read_status
    line = str(self.fp.readline(_MAXLINE + 1), "iso-8859-1")
  File "/usr/lib/python3.5/socket.py", line 575, in readinto
    return self._sock.recv_into(b)
  File "/usr/lib/python3.5/ssl.py", line 929, in recv_into
    return self.read(nbytes, buffer)
  File "/usr/lib/python3.5/ssl.py", line 791, in read
    return self._sslobj.read(len, buffer)
  File "/usr/lib/python3.5/ssl.py", line 575, in read
    v = self._sslobj.read(len, buffer)
KeyboardInterrupt
ERROR:root:Except on unfollow... Looks like a network error
Traceback (most recent call last):
  File "/home/morteza/venvs/instapy/lib/python3.5/site-packages/requests/packages/urllib3/connectionpool.py", line 379, in _make_request
    httplib_response = conn.getresponse(buffering=True)
TypeError: getresponse() got an unexpected keyword argument 'buffering'

During handling of the above exception, another exception occurred:

Traceback (most recent call last):
  File "/home/morteza/Code/instagram_bot/bot/src/instabot.py", line 643, in unfollow_on_cleanup
    unfollow = self.s.post(url_unfollow)
  File "/home/morteza/venvs/instapy/lib/python3.5/site-packages/requests/sessions.py", line 535, in post
    return self.request('POST', url, data=data, json=json, **kwargs)
  File "/home/morteza/venvs/instapy/lib/python3.5/site-packages/requests/sessions.py", line 488, in request
    resp = self.send(prep, **send_kwargs)
  File "/home/morteza/venvs/instapy/lib/python3.5/site-packages/requests/sessions.py", line 609, in send
    r = adapter.send(request, **kwargs)
  File "/home/morteza/venvs/instapy/lib/python3.5/site-packages/requests/adapters.py", line 423, in send
    timeout=timeout
  File "/home/morteza/venvs/instapy/lib/python3.5/site-packages/requests/packages/urllib3/connectionpool.py", line 600, in urlopen
    chunked=chunked)
  File "/home/morteza/venvs/instapy/lib/python3.5/site-packages/requests/packages/urllib3/connectionpool.py", line 382, in _make_request
    httplib_response = conn.getresponse()
  File "/usr/lib/python3.5/http/client.py", line 1197, in getresponse
    response.begin()
  File "/usr/lib/python3.5/http/client.py", line 297, in begin
    version, status, reason = self._read_status()
  File "/usr/lib/python3.5/http/client.py", line 258, in _read_status
    line = str(self.fp.readline(_MAXLINE + 1), "iso-8859-1")
  File "/usr/lib/python3.5/socket.py", line 575, in readinto
    return self._sock.recv_into(b)
  File "/usr/lib/python3.5/ssl.py", line 929, in recv_into
    return self.read(nbytes, buffer)
  File "/usr/lib/python3.5/ssl.py", line 791, in read
    return self._sslobj.read(len, buffer)
  File "/usr/lib/python3.5/ssl.py", line 575, in read
    v = self._sslobj.read(len, buffer)
KeyboardInterrupt
ERROR:root:Except on unfollow... Looks like a network error
Traceback (most recent call last):
  File "/home/morteza/venvs/instapy/lib/python3.5/site-packages/requests/packages/urllib3/connectionpool.py", line 379, in _make_request
    httplib_response = conn.getresponse(buffering=True)
TypeError: getresponse() got an unexpected keyword argument 'buffering'

During handling of the above exception, another exception occurred:

Traceback (most recent call last):
  File "/home/morteza/Code/instagram_bot/bot/src/instabot.py", line 643, in unfollow_on_cleanup
    unfollow = self.s.post(url_unfollow)
  File "/home/morteza/venvs/instapy/lib/python3.5/site-packages/requests/sessions.py", line 535, in post
    return self.request('POST', url, data=data, json=json, **kwargs)
  File "/home/morteza/venvs/instapy/lib/python3.5/site-packages/requests/sessions.py", line 488, in request
    resp = self.send(prep, **send_kwargs)
  File "/home/morteza/venvs/instapy/lib/python3.5/site-packages/requests/sessions.py", line 609, in send
    r = adapter.send(request, **kwargs)
  File "/home/morteza/venvs/instapy/lib/python3.5/site-packages/requests/adapters.py", line 423, in send
    timeout=timeout
  File "/home/morteza/venvs/instapy/lib/python3.5/site-packages/requests/packages/urllib3/connectionpool.py", line 600, in urlopen
    chunked=chunked)
  File "/home/morteza/venvs/instapy/lib/python3.5/site-packages/requests/packages/urllib3/connectionpool.py", line 382, in _make_request
    httplib_response = conn.getresponse()
  File "/usr/lib/python3.5/http/client.py", line 1197, in getresponse
    response.begin()
  File "/usr/lib/python3.5/http/client.py", line 297, in begin
    version, status, reason = self._read_status()
  File "/usr/lib/python3.5/http/client.py", line 258, in _read_status
    line = str(self.fp.readline(_MAXLINE + 1), "iso-8859-1")
  File "/usr/lib/python3.5/socket.py", line 575, in readinto
    return self._sock.recv_into(b)
  File "/usr/lib/python3.5/ssl.py", line 929, in recv_into
    return self.read(nbytes, buffer)
  File "/usr/lib/python3.5/ssl.py", line 791, in read
    return self._sslobj.read(len, buffer)
  File "/usr/lib/python3.5/ssl.py", line 575, in read
    v = self._sslobj.read(len, buffer)
KeyboardInterrupt
ERROR:root:Except on unfollow... Looks like a network error
Traceback (most recent call last):
  File "/home/morteza/Code/instagram_bot/bot/src/instabot.py", line 643, in unfollow_on_cleanup
    unfollow = self.s.post(url_unfollow)
  File "/home/morteza/venvs/instapy/lib/python3.5/site-packages/requests/sessions.py", line 535, in post
    return self.request('POST', url, data=data, json=json, **kwargs)
  File "/home/morteza/venvs/instapy/lib/python3.5/site-packages/requests/sessions.py", line 488, in request
    resp = self.send(prep, **send_kwargs)
  File "/home/morteza/venvs/instapy/lib/python3.5/site-packages/requests/sessions.py", line 609, in send
    r = adapter.send(request, **kwargs)
  File "/home/morteza/venvs/instapy/lib/python3.5/site-packages/requests/adapters.py", line 423, in send
    timeout=timeout
  File "/home/morteza/venvs/instapy/lib/python3.5/site-packages/requests/packages/urllib3/connectionpool.py", line 600, in urlopen
    chunked=chunked)
  File "/home/morteza/venvs/instapy/lib/python3.5/site-packages/requests/packages/urllib3/connectionpool.py", line 345, in _make_request
    self._validate_conn(conn)
  File "/home/morteza/venvs/instapy/lib/python3.5/site-packages/requests/packages/urllib3/connectionpool.py", line 844, in _validate_conn
    conn.connect()
  File "/home/morteza/venvs/instapy/lib/python3.5/site-packages/requests/packages/urllib3/connection.py", line 326, in connect
    ssl_context=context)
  File "/home/morteza/venvs/instapy/lib/python3.5/site-packages/requests/packages/urllib3/util/ssl_.py", line 324, in ssl_wrap_socket
    return context.wrap_socket(sock, server_hostname=server_hostname)
  File "/usr/lib/python3.5/ssl.py", line 377, in wrap_socket
    _context=self)
  File "/usr/lib/python3.5/ssl.py", line 752, in __init__
    self.do_handshake()
  File "/usr/lib/python3.5/ssl.py", line 988, in do_handshake
    self._sslobj.do_handshake()
  File "/usr/lib/python3.5/ssl.py", line 633, in do_handshake
    self._sslobj.do_handshake()
KeyboardInterrupt
ERROR:root:Except on unfollow... Looks like a network error
Traceback (most recent call last):
  File "/home/morteza/Code/instagram_bot/bot/src/instabot.py", line 643, in unfollow_on_cleanup
    unfollow = self.s.post(url_unfollow)
  File "/home/morteza/venvs/instapy/lib/python3.5/site-packages/requests/sessions.py", line 535, in post
    return self.request('POST', url, data=data, json=json, **kwargs)
  File "/home/morteza/venvs/instapy/lib/python3.5/site-packages/requests/sessions.py", line 488, in request
    resp = self.send(prep, **send_kwargs)
  File "/home/morteza/venvs/instapy/lib/python3.5/site-packages/requests/sessions.py", line 609, in send
    r = adapter.send(request, **kwargs)
  File "/home/morteza/venvs/instapy/lib/python3.5/site-packages/requests/adapters.py", line 423, in send
    timeout=timeout
  File "/home/morteza/venvs/instapy/lib/python3.5/site-packages/requests/packages/urllib3/connectionpool.py", line 600, in urlopen
    chunked=chunked)
  File "/home/morteza/venvs/instapy/lib/python3.5/site-packages/requests/packages/urllib3/connectionpool.py", line 345, in _make_request
    self._validate_conn(conn)
  File "/home/morteza/venvs/instapy/lib/python3.5/site-packages/requests/packages/urllib3/connectionpool.py", line 844, in _validate_conn
    conn.connect()
  File "/home/morteza/venvs/instapy/lib/python3.5/site-packages/requests/packages/urllib3/connection.py", line 284, in connect
    conn = self._new_conn()
  File "/home/morteza/venvs/instapy/lib/python3.5/site-packages/requests/packages/urllib3/connection.py", line 141, in _new_conn
    (self.host, self.port), self.timeout, **extra_kw)
  File "/home/morteza/venvs/instapy/lib/python3.5/site-packages/requests/packages/urllib3/util/connection.py", line 73, in create_connection
    sock.connect(sa)
KeyboardInterrupt
ERROR:root:Except on get_username_by_user_id
Traceback (most recent call last):
  File "/home/morteza/Code/instagram_bot/bot/src/instabot.py", line 405, in get_username_by_user_id
    r = self.s.get(url_info, headers="")
  File "/home/morteza/venvs/instapy/lib/python3.5/site-packages/requests/sessions.py", line 501, in get
    return self.request('GET', url, **kwargs)
  File "/home/morteza/venvs/instapy/lib/python3.5/site-packages/requests/sessions.py", line 488, in request
    resp = self.send(prep, **send_kwargs)
  File "/home/morteza/venvs/instapy/lib/python3.5/site-packages/requests/sessions.py", line 609, in send
    r = adapter.send(request, **kwargs)
  File "/home/morteza/venvs/instapy/lib/python3.5/site-packages/requests/adapters.py", line 423, in send
    timeout=timeout
  File "/home/morteza/venvs/instapy/lib/python3.5/site-packages/requests/packages/urllib3/connectionpool.py", line 600, in urlopen
    chunked=chunked)
  File "/home/morteza/venvs/instapy/lib/python3.5/site-packages/requests/packages/urllib3/connectionpool.py", line 345, in _make_request
    self._validate_conn(conn)
  File "/home/morteza/venvs/instapy/lib/python3.5/site-packages/requests/packages/urllib3/connectionpool.py", line 844, in _validate_conn
    conn.connect()
  File "/home/morteza/venvs/instapy/lib/python3.5/site-packages/requests/packages/urllib3/connection.py", line 284, in connect
    conn = self._new_conn()
  File "/home/morteza/venvs/instapy/lib/python3.5/site-packages/requests/packages/urllib3/connection.py", line 141, in _new_conn
    (self.host, self.port), self.timeout, **extra_kw)
  File "/home/morteza/venvs/instapy/lib/python3.5/site-packages/requests/packages/urllib3/util/connection.py", line 73, in create_connection
    sock.connect(sa)
KeyboardInterrupt
ERROR:root:Except on follow!
Traceback (most recent call last):
  File "/home/morteza/Code/instagram_bot/bot/src/instabot.py", line 616, in follow
    insert_username(self, user_id=user_id, username=username)
  File "/home/morteza/Code/instagram_bot/bot/src/sql_updates.py", line 74, in insert_username
    VALUES('"+user_id+"','"+username+"','"+ str(now) +"')")
TypeError: Can't convert 'bool' object to str implicitly
ERROR:root:Except on auto_unfollow!
Traceback (most recent call last):
  File "/home/morteza/Code/instagram_bot/bot/src/instabot.py", line 876, in auto_unfollow
    all_data = json.loads(r.text)
  File "/usr/lib/python3.5/json/__init__.py", line 319, in loads
    return _default_decoder.decode(s)
  File "/usr/lib/python3.5/json/decoder.py", line 339, in decode
    obj, end = self.raw_decode(s, idx=_w(s, 0).end())
  File "/usr/lib/python3.5/json/decoder.py", line 357, in raw_decode
    raise JSONDecodeError("Expecting value", s, err.value) from None
json.decoder.JSONDecodeError: Expecting value: line 1 column 1 (char 0)
ERROR:root:Logout error!
Traceback (most recent call last):
  File "/home/morteza/venvs/instapy/lib/python3.5/site-packages/requests/packages/urllib3/connectionpool.py", line 379, in _make_request
    httplib_response = conn.getresponse(buffering=True)
TypeError: getresponse() got an unexpected keyword argument 'buffering'

During handling of the above exception, another exception occurred:

Traceback (most recent call last):
  File "/home/morteza/Code/instagram_bot/bot/src/instabot.py", line 322, in logout
    logout = self.s.post(self.url_logout, data=logout_post)
  File "/home/morteza/venvs/instapy/lib/python3.5/site-packages/requests/sessions.py", line 535, in post
    return self.request('POST', url, data=data, json=json, **kwargs)
  File "/home/morteza/venvs/instapy/lib/python3.5/site-packages/requests/sessions.py", line 488, in request
    resp = self.send(prep, **send_kwargs)
  File "/home/morteza/venvs/instapy/lib/python3.5/site-packages/requests/sessions.py", line 609, in send
    r = adapter.send(request, **kwargs)
  File "/home/morteza/venvs/instapy/lib/python3.5/site-packages/requests/adapters.py", line 423, in send
    timeout=timeout
  File "/home/morteza/venvs/instapy/lib/python3.5/site-packages/requests/packages/urllib3/connectionpool.py", line 600, in urlopen
    chunked=chunked)
  File "/home/morteza/venvs/instapy/lib/python3.5/site-packages/requests/packages/urllib3/connectionpool.py", line 382, in _make_request
    httplib_response = conn.getresponse()
  File "/usr/lib/python3.5/http/client.py", line 1197, in getresponse
    response.begin()
  File "/usr/lib/python3.5/http/client.py", line 297, in begin
    version, status, reason = self._read_status()
  File "/usr/lib/python3.5/http/client.py", line 258, in _read_status
    line = str(self.fp.readline(_MAXLINE + 1), "iso-8859-1")
  File "/usr/lib/python3.5/socket.py", line 575, in readinto
    return self._sock.recv_into(b)
  File "/usr/lib/python3.5/ssl.py", line 929, in recv_into
    return self.read(nbytes, buffer)
  File "/usr/lib/python3.5/ssl.py", line 791, in read
    return self._sslobj.read(len, buffer)
  File "/usr/lib/python3.5/ssl.py", line 575, in read
    v = self._sslobj.read(len, buffer)
KeyboardInterrupt
ERROR:root:get_media_id_by_tag
Traceback (most recent call last):
  File "/home/morteza/Code/instagram_bot/bot/src/instabot.py", line 359, in get_media_id_by_tag
    all_data = json.loads(r.text)
  File "/usr/lib/python3.5/json/__init__.py", line 319, in loads
    return _default_decoder.decode(s)
  File "/usr/lib/python3.5/json/decoder.py", line 339, in decode
    obj, end = self.raw_decode(s, idx=_w(s, 0).end())
  File "/usr/lib/python3.5/json/decoder.py", line 357, in raw_decode
    raise JSONDecodeError("Expecting value", s, err.value) from None
json.decoder.JSONDecodeError: Expecting value: line 1 column 1 (char 0)
ERROR:root:get_media_id_by_tag
Traceback (most recent call last):
  File "/home/morteza/Code/instagram_bot/bot/src/instabot.py", line 359, in get_media_id_by_tag
    all_data = json.loads(r.text)
  File "/usr/lib/python3.5/json/__init__.py", line 319, in loads
    return _default_decoder.decode(s)
  File "/usr/lib/python3.5/json/decoder.py", line 339, in decode
    obj, end = self.raw_decode(s, idx=_w(s, 0).end())
  File "/usr/lib/python3.5/json/decoder.py", line 357, in raw_decode
    raise JSONDecodeError("Expecting value", s, err.value) from None
json.decoder.JSONDecodeError: Expecting value: line 1 column 1 (char 0)
ERROR:root:Except on auto_unfollow!
Traceback (most recent call last):
  File "/home/morteza/Code/instagram_bot/bot/src/instabot.py", line 878, in auto_unfollow
    all_data = json.loads(r.text)
  File "/usr/lib/python3.5/json/__init__.py", line 319, in loads
    return _default_decoder.decode(s)
  File "/usr/lib/python3.5/json/decoder.py", line 339, in decode
    obj, end = self.raw_decode(s, idx=_w(s, 0).end())
  File "/usr/lib/python3.5/json/decoder.py", line 357, in raw_decode
    raise JSONDecodeError("Expecting value", s, err.value) from None
json.decoder.JSONDecodeError: Expecting value: line 1 column 1 (char 0)
ERROR:root:get_media_id_by_tag
Traceback (most recent call last):
  File "/home/morteza/Code/instagram_bot/bot/src/instabot.py", line 360, in get_media_id_by_tag
    all_data = json.loads(r.text)
  File "/usr/lib/python3.5/json/__init__.py", line 319, in loads
    return _default_decoder.decode(s)
  File "/usr/lib/python3.5/json/decoder.py", line 339, in decode
    obj, end = self.raw_decode(s, idx=_w(s, 0).end())
  File "/usr/lib/python3.5/json/decoder.py", line 357, in raw_decode
    raise JSONDecodeError("Expecting value", s, err.value) from None
json.decoder.JSONDecodeError: Expecting value: line 1 column 1 (char 0)
ERROR:root:get_media_id_by_tag
Traceback (most recent call last):
  File "/home/morteza/Code/instagram_bot/bot/src/instabot.py", line 363, in get_media_id_by_tag
    all_data = json.loads(r.text)
  File "/usr/lib/python3.5/json/__init__.py", line 319, in loads
    return _default_decoder.decode(s)
  File "/usr/lib/python3.5/json/decoder.py", line 339, in decode
    obj, end = self.raw_decode(s, idx=_w(s, 0).end())
  File "/usr/lib/python3.5/json/decoder.py", line 357, in raw_decode
    raise JSONDecodeError("Expecting value", s, err.value) from None
json.decoder.JSONDecodeError: Expecting value: line 1 column 1 (char 0)
ERROR:root:get_media_id_by_tag
Traceback (most recent call last):
  File "/home/morteza/Code/instagram_bot/bot/src/instabot.py", line 363, in get_media_id_by_tag
    all_data = json.loads(r.text)
  File "/usr/lib/python3.5/json/__init__.py", line 319, in loads
    return _default_decoder.decode(s)
  File "/usr/lib/python3.5/json/decoder.py", line 339, in decode
    obj, end = self.raw_decode(s, idx=_w(s, 0).end())
  File "/usr/lib/python3.5/json/decoder.py", line 357, in raw_decode
    raise JSONDecodeError("Expecting value", s, err.value) from None
json.decoder.JSONDecodeError: Expecting value: line 1 column 1 (char 0)
ERROR:root:get_media_id_by_tag
Traceback (most recent call last):
  File "/home/morteza/Code/instagram_bot/bot/src/instabot.py", line 363, in get_media_id_by_tag
    all_data = json.loads(r.text)
  File "/usr/lib/python3.5/json/__init__.py", line 319, in loads
    return _default_decoder.decode(s)
  File "/usr/lib/python3.5/json/decoder.py", line 339, in decode
    obj, end = self.raw_decode(s, idx=_w(s, 0).end())
  File "/usr/lib/python3.5/json/decoder.py", line 357, in raw_decode
    raise JSONDecodeError("Expecting value", s, err.value) from None
json.decoder.JSONDecodeError: Expecting value: line 1 column 1 (char 0)
ERROR:root:get_media_id_by_tag
Traceback (most recent call last):
  File "/home/morteza/Code/instagram_bot/bot/src/instabot.py", line 362, in get_media_id_by_tag
    r = self.s.get(url_tag)
  File "/home/morteza/venvs/instapy/lib/python3.5/site-packages/requests/sessions.py", line 501, in get
    return self.request('GET', url, **kwargs)
  File "/home/morteza/venvs/instapy/lib/python3.5/site-packages/requests/sessions.py", line 488, in request
    resp = self.send(prep, **send_kwargs)
  File "/home/morteza/venvs/instapy/lib/python3.5/site-packages/requests/sessions.py", line 641, in send
    r.content
  File "/home/morteza/venvs/instapy/lib/python3.5/site-packages/requests/models.py", line 797, in content
    self._content = bytes().join(self.iter_content(CONTENT_CHUNK_SIZE)) or bytes()
  File "/home/morteza/venvs/instapy/lib/python3.5/site-packages/requests/models.py", line 719, in generate
    for chunk in self.raw.stream(chunk_size, decode_content=True):
  File "/home/morteza/venvs/instapy/lib/python3.5/site-packages/requests/packages/urllib3/response.py", line 432, in stream
    data = self.read(amt=amt, decode_content=decode_content)
  File "/home/morteza/venvs/instapy/lib/python3.5/site-packages/requests/packages/urllib3/response.py", line 380, in read
    data = self._fp.read(amt)
  File "/usr/lib/python3.5/http/client.py", line 448, in read
    n = self.readinto(b)
  File "/usr/lib/python3.5/http/client.py", line 488, in readinto
    n = self.fp.readinto(b)
  File "/usr/lib/python3.5/socket.py", line 575, in readinto
    return self._sock.recv_into(b)
  File "/usr/lib/python3.5/ssl.py", line 929, in recv_into
    return self.read(nbytes, buffer)
  File "/usr/lib/python3.5/ssl.py", line 791, in read
    return self._sslobj.read(len, buffer)
  File "/usr/lib/python3.5/ssl.py", line 575, in read
    v = self._sslobj.read(len, buffer)
KeyboardInterrupt
ERROR:root:Except on unfollow... Looks like a network error
Traceback (most recent call last):
  File "/home/morteza/Code/instagram_bot/bot/src/instabot.py", line 649, in unfollow_on_cleanup
    unfollow = self.s.post(url_unfollow)
  File "/home/morteza/venvs/instapy/lib/python3.5/site-packages/requests/sessions.py", line 535, in post
    return self.request('POST', url, data=data, json=json, **kwargs)
  File "/home/morteza/venvs/instapy/lib/python3.5/site-packages/requests/sessions.py", line 488, in request
    resp = self.send(prep, **send_kwargs)
  File "/home/morteza/venvs/instapy/lib/python3.5/site-packages/requests/sessions.py", line 609, in send
    r = adapter.send(request, **kwargs)
  File "/home/morteza/venvs/instapy/lib/python3.5/site-packages/requests/adapters.py", line 423, in send
    timeout=timeout
  File "/home/morteza/venvs/instapy/lib/python3.5/site-packages/requests/packages/urllib3/connectionpool.py", line 600, in urlopen
    chunked=chunked)
  File "/home/morteza/venvs/instapy/lib/python3.5/site-packages/requests/packages/urllib3/connectionpool.py", line 345, in _make_request
    self._validate_conn(conn)
  File "/home/morteza/venvs/instapy/lib/python3.5/site-packages/requests/packages/urllib3/connectionpool.py", line 844, in _validate_conn
    conn.connect()
  File "/home/morteza/venvs/instapy/lib/python3.5/site-packages/requests/packages/urllib3/connection.py", line 284, in connect
    conn = self._new_conn()
  File "/home/morteza/venvs/instapy/lib/python3.5/site-packages/requests/packages/urllib3/connection.py", line 141, in _new_conn
    (self.host, self.port), self.timeout, **extra_kw)
  File "/home/morteza/venvs/instapy/lib/python3.5/site-packages/requests/packages/urllib3/util/connection.py", line 60, in create_connection
    for res in socket.getaddrinfo(host, port, family, socket.SOCK_STREAM):
  File "/usr/lib/python3.5/socket.py", line 732, in getaddrinfo
    for res in _socket.getaddrinfo(host, port, family, type, proto, flags):
KeyboardInterrupt
ERROR:root:get_media_id_by_tag
Traceback (most recent call last):
  File "/home/morteza/Code/instagram_bot/bot/src/instabot.py", line 363, in get_media_id_by_tag
    all_data = json.loads(r.text)
  File "/usr/lib/python3.5/json/__init__.py", line 319, in loads
    return _default_decoder.decode(s)
  File "/usr/lib/python3.5/json/decoder.py", line 339, in decode
    obj, end = self.raw_decode(s, idx=_w(s, 0).end())
  File "/usr/lib/python3.5/json/decoder.py", line 357, in raw_decode
    raise JSONDecodeError("Expecting value", s, err.value) from None
json.decoder.JSONDecodeError: Expecting value: line 1 column 1 (char 0)
ERROR:root:get_media_id_by_tag
Traceback (most recent call last):
  File "/home/morteza/Code/instagram_bot/bot/src/instabot.py", line 363, in get_media_id_by_tag
    all_data = json.loads(r.text)
  File "/usr/lib/python3.5/json/__init__.py", line 319, in loads
    return _default_decoder.decode(s)
  File "/usr/lib/python3.5/json/decoder.py", line 339, in decode
    obj, end = self.raw_decode(s, idx=_w(s, 0).end())
  File "/usr/lib/python3.5/json/decoder.py", line 357, in raw_decode
    raise JSONDecodeError("Expecting value", s, err.value) from None
json.decoder.JSONDecodeError: Expecting value: line 1 column 1 (char 0)
ERROR:root:get_media_id_by_tag
Traceback (most recent call last):
  File "/home/morteza/Code/instagram_bot/bot/src/instabot.py", line 363, in get_media_id_by_tag
    all_data = json.loads(r.text)
  File "/usr/lib/python3.5/json/__init__.py", line 319, in loads
    return _default_decoder.decode(s)
  File "/usr/lib/python3.5/json/decoder.py", line 339, in decode
    obj, end = self.raw_decode(s, idx=_w(s, 0).end())
  File "/usr/lib/python3.5/json/decoder.py", line 357, in raw_decode
    raise JSONDecodeError("Expecting value", s, err.value) from None
json.decoder.JSONDecodeError: Expecting value: line 1 column 1 (char 0)
ERROR:root:get_media_id_by_tag
Traceback (most recent call last):
  File "/home/morteza/Code/instagram_bot/bot/src/instabot.py", line 363, in get_media_id_by_tag
    all_data = json.loads(r.text)
  File "/usr/lib/python3.5/json/__init__.py", line 319, in loads
    return _default_decoder.decode(s)
  File "/usr/lib/python3.5/json/decoder.py", line 339, in decode
    obj, end = self.raw_decode(s, idx=_w(s, 0).end())
  File "/usr/lib/python3.5/json/decoder.py", line 357, in raw_decode
    raise JSONDecodeError("Expecting value", s, err.value) from None
json.decoder.JSONDecodeError: Expecting value: line 1 column 1 (char 0)
ERROR:root:get_media_id_by_tag
Traceback (most recent call last):
  File "/home/morteza/Code/instagram_bot/bot/src/instabot.py", line 363, in get_media_id_by_tag
    all_data = json.loads(r.text)
  File "/usr/lib/python3.5/json/__init__.py", line 319, in loads
    return _default_decoder.decode(s)
  File "/usr/lib/python3.5/json/decoder.py", line 339, in decode
    obj, end = self.raw_decode(s, idx=_w(s, 0).end())
  File "/usr/lib/python3.5/json/decoder.py", line 357, in raw_decode
    raise JSONDecodeError("Expecting value", s, err.value) from None
json.decoder.JSONDecodeError: Expecting value: line 1 column 1 (char 0)
ERROR:root:get_media_id_by_tag
Traceback (most recent call last):
  File "/home/morteza/Code/instagram_bot/bot/src/instabot.py", line 363, in get_media_id_by_tag
    all_data = json.loads(r.text)
  File "/usr/lib/python3.5/json/__init__.py", line 319, in loads
    return _default_decoder.decode(s)
  File "/usr/lib/python3.5/json/decoder.py", line 339, in decode
    obj, end = self.raw_decode(s, idx=_w(s, 0).end())
  File "/usr/lib/python3.5/json/decoder.py", line 357, in raw_decode
    raise JSONDecodeError("Expecting value", s, err.value) from None
json.decoder.JSONDecodeError: Expecting value: line 1 column 1 (char 0)
ERROR:root:get_media_id_by_tag
Traceback (most recent call last):
  File "/home/morteza/Code/instagram_bot/bot/src/instabot.py", line 363, in get_media_id_by_tag
    all_data = json.loads(r.text)
  File "/usr/lib/python3.5/json/__init__.py", line 319, in loads
    return _default_decoder.decode(s)
  File "/usr/lib/python3.5/json/decoder.py", line 339, in decode
    obj, end = self.raw_decode(s, idx=_w(s, 0).end())
  File "/usr/lib/python3.5/json/decoder.py", line 357, in raw_decode
    raise JSONDecodeError("Expecting value", s, err.value) from None
json.decoder.JSONDecodeError: Expecting value: line 1 column 1 (char 0)
ERROR:root:get_media_id_by_tag
Traceback (most recent call last):
  File "/home/morteza/Code/instagram_bot/bot/src/instabot.py", line 363, in get_media_id_by_tag
    all_data = json.loads(r.text)
  File "/usr/lib/python3.5/json/__init__.py", line 319, in loads
    return _default_decoder.decode(s)
  File "/usr/lib/python3.5/json/decoder.py", line 339, in decode
    obj, end = self.raw_decode(s, idx=_w(s, 0).end())
  File "/usr/lib/python3.5/json/decoder.py", line 357, in raw_decode
    raise JSONDecodeError("Expecting value", s, err.value) from None
json.decoder.JSONDecodeError: Expecting value: line 1 column 1 (char 0)
ERROR:root:get_media_id_by_tag
Traceback (most recent call last):
  File "/home/morteza/Code/instagram_bot/bot/src/instabot.py", line 363, in get_media_id_by_tag
    all_data = json.loads(r.text)
  File "/usr/lib/python3.5/json/__init__.py", line 319, in loads
    return _default_decoder.decode(s)
  File "/usr/lib/python3.5/json/decoder.py", line 339, in decode
    obj, end = self.raw_decode(s, idx=_w(s, 0).end())
  File "/usr/lib/python3.5/json/decoder.py", line 357, in raw_decode
    raise JSONDecodeError("Expecting value", s, err.value) from None
json.decoder.JSONDecodeError: Expecting value: line 1 column 1 (char 0)
ERROR:root:get_media_id_by_tag
Traceback (most recent call last):
  File "/home/morteza/Code/instagram_bot/bot/src/instabot.py", line 363, in get_media_id_by_tag
    all_data = json.loads(r.text)
  File "/usr/lib/python3.5/json/__init__.py", line 319, in loads
    return _default_decoder.decode(s)
  File "/usr/lib/python3.5/json/decoder.py", line 339, in decode
    obj, end = self.raw_decode(s, idx=_w(s, 0).end())
  File "/usr/lib/python3.5/json/decoder.py", line 357, in raw_decode
    raise JSONDecodeError("Expecting value", s, err.value) from None
json.decoder.JSONDecodeError: Expecting value: line 1 column 1 (char 0)
ERROR:root:get_media_id_by_tag
Traceback (most recent call last):
  File "/home/morteza/Code/instagram_bot/bot/src/instabot.py", line 363, in get_media_id_by_tag
    all_data = json.loads(r.text)
  File "/usr/lib/python3.5/json/__init__.py", line 319, in loads
    return _default_decoder.decode(s)
  File "/usr/lib/python3.5/json/decoder.py", line 339, in decode
    obj, end = self.raw_decode(s, idx=_w(s, 0).end())
  File "/usr/lib/python3.5/json/decoder.py", line 357, in raw_decode
    raise JSONDecodeError("Expecting value", s, err.value) from None
json.decoder.JSONDecodeError: Expecting value: line 1 column 1 (char 0)
ERROR:root:get_media_id_by_tag
Traceback (most recent call last):
  File "/home/morteza/Code/instagram_bot/bot/src/instabot.py", line 363, in get_media_id_by_tag
    all_data = json.loads(r.text)
  File "/usr/lib/python3.5/json/__init__.py", line 319, in loads
    return _default_decoder.decode(s)
  File "/usr/lib/python3.5/json/decoder.py", line 339, in decode
    obj, end = self.raw_decode(s, idx=_w(s, 0).end())
  File "/usr/lib/python3.5/json/decoder.py", line 357, in raw_decode
    raise JSONDecodeError("Expecting value", s, err.value) from None
json.decoder.JSONDecodeError: Expecting value: line 1 column 1 (char 0)
ERROR:root:get_media_id_by_tag
Traceback (most recent call last):
  File "/home/morteza/Code/instagram_bot/bot/src/instabot.py", line 363, in get_media_id_by_tag
    all_data = json.loads(r.text)
  File "/usr/lib/python3.5/json/__init__.py", line 319, in loads
    return _default_decoder.decode(s)
  File "/usr/lib/python3.5/json/decoder.py", line 339, in decode
    obj, end = self.raw_decode(s, idx=_w(s, 0).end())
  File "/usr/lib/python3.5/json/decoder.py", line 357, in raw_decode
    raise JSONDecodeError("Expecting value", s, err.value) from None
json.decoder.JSONDecodeError: Expecting value: line 1 column 1 (char 0)
ERROR:root:get_media_id_by_tag
Traceback (most recent call last):
  File "/home/morteza/Code/instagram_bot/bot/src/instabot.py", line 363, in get_media_id_by_tag
    all_data = json.loads(r.text)
  File "/usr/lib/python3.5/json/__init__.py", line 319, in loads
    return _default_decoder.decode(s)
  File "/usr/lib/python3.5/json/decoder.py", line 339, in decode
    obj, end = self.raw_decode(s, idx=_w(s, 0).end())
  File "/usr/lib/python3.5/json/decoder.py", line 357, in raw_decode
    raise JSONDecodeError("Expecting value", s, err.value) from None
json.decoder.JSONDecodeError: Expecting value: line 1 column 1 (char 0)
ERROR:root:get_media_id_by_tag
Traceback (most recent call last):
  File "/home/morteza/Code/instagram_bot/bot/src/instabot.py", line 363, in get_media_id_by_tag
    all_data = json.loads(r.text)
  File "/usr/lib/python3.5/json/__init__.py", line 319, in loads
    return _default_decoder.decode(s)
  File "/usr/lib/python3.5/json/decoder.py", line 339, in decode
    obj, end = self.raw_decode(s, idx=_w(s, 0).end())
  File "/usr/lib/python3.5/json/decoder.py", line 357, in raw_decode
    raise JSONDecodeError("Expecting value", s, err.value) from None
json.decoder.JSONDecodeError: Expecting value: line 1 column 1 (char 0)
ERROR:root:get_media_id_by_tag
Traceback (most recent call last):
  File "/home/morteza/Code/instagram_bot/bot/src/instabot.py", line 363, in get_media_id_by_tag
    all_data = json.loads(r.text)
  File "/usr/lib/python3.5/json/__init__.py", line 319, in loads
    return _default_decoder.decode(s)
  File "/usr/lib/python3.5/json/decoder.py", line 339, in decode
    obj, end = self.raw_decode(s, idx=_w(s, 0).end())
  File "/usr/lib/python3.5/json/decoder.py", line 357, in raw_decode
    raise JSONDecodeError("Expecting value", s, err.value) from None
json.decoder.JSONDecodeError: Expecting value: line 1 column 1 (char 0)
ERROR:root:get_media_id_by_tag
Traceback (most recent call last):
  File "/home/morteza/Code/instagram_bot/bot/src/instabot.py", line 363, in get_media_id_by_tag
    all_data = json.loads(r.text)
  File "/usr/lib/python3.5/json/__init__.py", line 319, in loads
    return _default_decoder.decode(s)
  File "/usr/lib/python3.5/json/decoder.py", line 339, in decode
    obj, end = self.raw_decode(s, idx=_w(s, 0).end())
  File "/usr/lib/python3.5/json/decoder.py", line 357, in raw_decode
    raise JSONDecodeError("Expecting value", s, err.value) from None
json.decoder.JSONDecodeError: Expecting value: line 1 column 1 (char 0)
ERROR:root:get_media_id_by_tag
Traceback (most recent call last):
  File "/home/morteza/Code/instagram_bot/bot/src/instabot.py", line 363, in get_media_id_by_tag
    all_data = json.loads(r.text)
  File "/usr/lib/python3.5/json/__init__.py", line 319, in loads
    return _default_decoder.decode(s)
  File "/usr/lib/python3.5/json/decoder.py", line 339, in decode
    obj, end = self.raw_decode(s, idx=_w(s, 0).end())
  File "/usr/lib/python3.5/json/decoder.py", line 357, in raw_decode
    raise JSONDecodeError("Expecting value", s, err.value) from None
json.decoder.JSONDecodeError: Expecting value: line 1 column 1 (char 0)
ERROR:root:Logout error!
Traceback (most recent call last):
  File "/home/morteza/venvs/instapy/lib/python3.5/site-packages/requests/packages/urllib3/connectionpool.py", line 379, in _make_request
    httplib_response = conn.getresponse(buffering=True)
TypeError: getresponse() got an unexpected keyword argument 'buffering'

During handling of the above exception, another exception occurred:

Traceback (most recent call last):
  File "/home/morteza/Code/instagram_bot/bot/src/instabot.py", line 328, in logout
    logout = self.s.post(self.url_logout, data=logout_post)
  File "/home/morteza/venvs/instapy/lib/python3.5/site-packages/requests/sessions.py", line 535, in post
    return self.request('POST', url, data=data, json=json, **kwargs)
  File "/home/morteza/venvs/instapy/lib/python3.5/site-packages/requests/sessions.py", line 488, in request
    resp = self.send(prep, **send_kwargs)
  File "/home/morteza/venvs/instapy/lib/python3.5/site-packages/requests/sessions.py", line 609, in send
    r = adapter.send(request, **kwargs)
  File "/home/morteza/venvs/instapy/lib/python3.5/site-packages/requests/adapters.py", line 423, in send
    timeout=timeout
  File "/home/morteza/venvs/instapy/lib/python3.5/site-packages/requests/packages/urllib3/connectionpool.py", line 600, in urlopen
    chunked=chunked)
  File "/home/morteza/venvs/instapy/lib/python3.5/site-packages/requests/packages/urllib3/connectionpool.py", line 382, in _make_request
    httplib_response = conn.getresponse()
  File "/usr/lib/python3.5/http/client.py", line 1197, in getresponse
    response.begin()
  File "/usr/lib/python3.5/http/client.py", line 297, in begin
    version, status, reason = self._read_status()
  File "/usr/lib/python3.5/http/client.py", line 258, in _read_status
    line = str(self.fp.readline(_MAXLINE + 1), "iso-8859-1")
  File "/usr/lib/python3.5/socket.py", line 575, in readinto
    return self._sock.recv_into(b)
  File "/usr/lib/python3.5/ssl.py", line 929, in recv_into
    return self.read(nbytes, buffer)
  File "/usr/lib/python3.5/ssl.py", line 791, in read
    return self._sslobj.read(len, buffer)
  File "/usr/lib/python3.5/ssl.py", line 575, in read
    v = self._sslobj.read(len, buffer)
KeyboardInterrupt
ERROR:root:get_media_id_by_tag
Traceback (most recent call last):
  File "/home/morteza/Code/instagram_bot/bot/src/instabot.py", line 363, in get_media_id_by_tag
    all_data = json.loads(r.text)
  File "/usr/lib/python3.5/json/__init__.py", line 319, in loads
    return _default_decoder.decode(s)
  File "/usr/lib/python3.5/json/decoder.py", line 339, in decode
    obj, end = self.raw_decode(s, idx=_w(s, 0).end())
  File "/usr/lib/python3.5/json/decoder.py", line 357, in raw_decode
    raise JSONDecodeError("Expecting value", s, err.value) from None
json.decoder.JSONDecodeError: Expecting value: line 1 column 1 (char 0)
ERROR:root:get_media_id_by_tag
Traceback (most recent call last):
  File "/home/morteza/Code/instagram_bot/bot/src/instabot.py", line 363, in get_media_id_by_tag
    all_data = json.loads(r.text)
  File "/usr/lib/python3.5/json/__init__.py", line 319, in loads
    return _default_decoder.decode(s)
  File "/usr/lib/python3.5/json/decoder.py", line 339, in decode
    obj, end = self.raw_decode(s, idx=_w(s, 0).end())
  File "/usr/lib/python3.5/json/decoder.py", line 357, in raw_decode
    raise JSONDecodeError("Expecting value", s, err.value) from None
json.decoder.JSONDecodeError: Expecting value: line 1 column 1 (char 0)
ERROR:root:get_media_id_by_tag
Traceback (most recent call last):
  File "/home/morteza/Code/instagram_bot/bot/src/instabot.py", line 363, in get_media_id_by_tag
    r = self.s.get(url_tag)
  File "/usr/lib/python3.5/json/__init__.py", line 319, in loads
    return _default_decoder.decode(s)
  File "/usr/lib/python3.5/json/decoder.py", line 339, in decode
    obj, end = self.raw_decode(s, idx=_w(s, 0).end())
  File "/usr/lib/python3.5/json/decoder.py", line 357, in raw_decode
    raise JSONDecodeError("Expecting value", s, err.value) from None
json.decoder.JSONDecodeError: Expecting value: line 1 column 1 (char 0)
ERROR:root:Except on comment!
Traceback (most recent call last):
  File "/home/morteza/venvs/instapy/lib/python3.5/site-packages/requests/packages/urllib3/connectionpool.py", line 379, in _make_request
    httplib_response = conn.getresponse(buffering=True)
TypeError: getresponse() got an unexpected keyword argument 'buffering'

During handling of the above exception, another exception occurred:

Traceback (most recent call last):
  File "/home/morteza/Code/instagram_bot/bot/src/instabot.py", line 601, in comment
    try:
  File "/home/morteza/venvs/instapy/lib/python3.5/site-packages/requests/sessions.py", line 535, in post
    return self.request('POST', url, data=data, json=json, **kwargs)
  File "/home/morteza/venvs/instapy/lib/python3.5/site-packages/requests/sessions.py", line 488, in request
    resp = self.send(prep, **send_kwargs)
  File "/home/morteza/venvs/instapy/lib/python3.5/site-packages/requests/sessions.py", line 609, in send
    r = adapter.send(request, **kwargs)
  File "/home/morteza/venvs/instapy/lib/python3.5/site-packages/requests/adapters.py", line 423, in send
    timeout=timeout
  File "/home/morteza/venvs/instapy/lib/python3.5/site-packages/requests/packages/urllib3/connectionpool.py", line 600, in urlopen
    chunked=chunked)
  File "/home/morteza/venvs/instapy/lib/python3.5/site-packages/requests/packages/urllib3/connectionpool.py", line 382, in _make_request
    httplib_response = conn.getresponse()
  File "/usr/lib/python3.5/http/client.py", line 1197, in getresponse
    response.begin()
  File "/usr/lib/python3.5/http/client.py", line 297, in begin
    version, status, reason = self._read_status()
  File "/usr/lib/python3.5/http/client.py", line 258, in _read_status
    line = str(self.fp.readline(_MAXLINE + 1), "iso-8859-1")
  File "/usr/lib/python3.5/socket.py", line 575, in readinto
    return self._sock.recv_into(b)
  File "/usr/lib/python3.5/ssl.py", line 929, in recv_into
    return self.read(nbytes, buffer)
  File "/usr/lib/python3.5/ssl.py", line 791, in read
    return self._sslobj.read(len, buffer)
  File "/usr/lib/python3.5/ssl.py", line 575, in read
    v = self._sslobj.read(len, buffer)
KeyboardInterrupt
ERROR:root:get_media_id_by_tag
Traceback (most recent call last):
  File "/home/morteza/Code/instagram_bot/bot/src/instabot.py", line 363, in get_media_id_by_tag
    r = self.s.get(url_tag)
  File "/usr/lib/python3.5/json/__init__.py", line 319, in loads
    return _default_decoder.decode(s)
  File "/usr/lib/python3.5/json/decoder.py", line 339, in decode
    obj, end = self.raw_decode(s, idx=_w(s, 0).end())
  File "/usr/lib/python3.5/json/decoder.py", line 357, in raw_decode
    raise JSONDecodeError("Expecting value", s, err.value) from None
json.decoder.JSONDecodeError: Expecting value: line 1 column 1 (char 0)
ERROR:root:get_media_id_by_tag
Traceback (most recent call last):
  File "/home/morteza/Code/instagram_bot/bot/src/instabot.py", line 363, in get_media_id_by_tag
    r = self.s.get(url_tag)
  File "/usr/lib/python3.5/json/__init__.py", line 319, in loads
    return _default_decoder.decode(s)
  File "/usr/lib/python3.5/json/decoder.py", line 339, in decode
    obj, end = self.raw_decode(s, idx=_w(s, 0).end())
  File "/usr/lib/python3.5/json/decoder.py", line 357, in raw_decode
    raise JSONDecodeError("Expecting value", s, err.value) from None
json.decoder.JSONDecodeError: Expecting value: line 1 column 1 (char 0)
ERROR:root:Except on comment!
Traceback (most recent call last):
  File "/home/morteza/venvs/instapy/lib/python3.5/site-packages/requests/packages/urllib3/connectionpool.py", line 379, in _make_request
    httplib_response = conn.getresponse(buffering=True)
TypeError: getresponse() got an unexpected keyword argument 'buffering'

During handling of the above exception, another exception occurred:

Traceback (most recent call last):
  File "/home/morteza/Code/instagram_bot/bot/src/instabot.py", line 601, in comment
    try:
  File "/home/morteza/venvs/instapy/lib/python3.5/site-packages/requests/sessions.py", line 535, in post
    return self.request('POST', url, data=data, json=json, **kwargs)
  File "/home/morteza/venvs/instapy/lib/python3.5/site-packages/requests/sessions.py", line 488, in request
    resp = self.send(prep, **send_kwargs)
  File "/home/morteza/venvs/instapy/lib/python3.5/site-packages/requests/sessions.py", line 609, in send
    r = adapter.send(request, **kwargs)
  File "/home/morteza/venvs/instapy/lib/python3.5/site-packages/requests/adapters.py", line 423, in send
    timeout=timeout
  File "/home/morteza/venvs/instapy/lib/python3.5/site-packages/requests/packages/urllib3/connectionpool.py", line 600, in urlopen
    chunked=chunked)
  File "/home/morteza/venvs/instapy/lib/python3.5/site-packages/requests/packages/urllib3/connectionpool.py", line 382, in _make_request
    httplib_response = conn.getresponse()
  File "/usr/lib/python3.5/http/client.py", line 1197, in getresponse
    response.begin()
  File "/usr/lib/python3.5/http/client.py", line 297, in begin
    version, status, reason = self._read_status()
  File "/usr/lib/python3.5/http/client.py", line 258, in _read_status
    line = str(self.fp.readline(_MAXLINE + 1), "iso-8859-1")
  File "/usr/lib/python3.5/socket.py", line 575, in readinto
    return self._sock.recv_into(b)
  File "/usr/lib/python3.5/ssl.py", line 929, in recv_into
    return self.read(nbytes, buffer)
  File "/usr/lib/python3.5/ssl.py", line 791, in read
    return self._sslobj.read(len, buffer)
  File "/usr/lib/python3.5/ssl.py", line 575, in read
    v = self._sslobj.read(len, buffer)
KeyboardInterrupt
ERROR:root:get_media_id_by_tag
Traceback (most recent call last):
  File "/home/morteza/Code/instagram_bot/bot/src/instabot.py", line 364, in get_media_id_by_tag
    all_data = json.loads(r.text)
  File "/usr/lib/python3.5/json/__init__.py", line 319, in loads
    return _default_decoder.decode(s)
  File "/usr/lib/python3.5/json/decoder.py", line 339, in decode
    obj, end = self.raw_decode(s, idx=_w(s, 0).end())
  File "/usr/lib/python3.5/json/decoder.py", line 357, in raw_decode
    raise JSONDecodeError("Expecting value", s, err.value) from None
json.decoder.JSONDecodeError: Expecting value: line 1 column 1 (char 0)
ERROR:root:get_media_id_by_tag
Traceback (most recent call last):
  File "/home/morteza/Code/instagram_bot/bot/src/instabot.py", line 364, in get_media_id_by_tag
    all_data = json.loads(r.text)
  File "/usr/lib/python3.5/json/__init__.py", line 319, in loads
    return _default_decoder.decode(s)
  File "/usr/lib/python3.5/json/decoder.py", line 339, in decode
    obj, end = self.raw_decode(s, idx=_w(s, 0).end())
  File "/usr/lib/python3.5/json/decoder.py", line 357, in raw_decode
    raise JSONDecodeError("Expecting value", s, err.value) from None
json.decoder.JSONDecodeError: Expecting value: line 1 column 1 (char 0)
ERROR:root:get_media_id_by_tag
Traceback (most recent call last):
  File "/home/morteza/Code/instagram_bot/bot/src/instabot.py", line 364, in get_media_id_by_tag
    all_data = json.loads(r.text)
  File "/usr/lib/python3.5/json/__init__.py", line 319, in loads
    return _default_decoder.decode(s)
  File "/usr/lib/python3.5/json/decoder.py", line 339, in decode
    obj, end = self.raw_decode(s, idx=_w(s, 0).end())
  File "/usr/lib/python3.5/json/decoder.py", line 357, in raw_decode
    raise JSONDecodeError("Expecting value", s, err.value) from None
json.decoder.JSONDecodeError: Expecting value: line 1 column 1 (char 0)
ERROR:root:get_media_id_by_tag
Traceback (most recent call last):
  File "/home/morteza/Code/instagram_bot/bot/src/instabot.py", line 364, in get_media_id_by_tag
    all_data = json.loads(r.text)
  File "/usr/lib/python3.5/json/__init__.py", line 319, in loads
    return _default_decoder.decode(s)
  File "/usr/lib/python3.5/json/decoder.py", line 339, in decode
    obj, end = self.raw_decode(s, idx=_w(s, 0).end())
  File "/usr/lib/python3.5/json/decoder.py", line 357, in raw_decode
    raise JSONDecodeError("Expecting value", s, err.value) from None
json.decoder.JSONDecodeError: Expecting value: line 1 column 1 (char 0)
ERROR:root:get_media_id_by_tag
Traceback (most recent call last):
  File "/home/morteza/Code/instagram_bot/bot/src/instabot.py", line 364, in get_media_id_by_tag
    all_data = json.loads(r.text)
  File "/usr/lib/python3.5/json/__init__.py", line 319, in loads
    return _default_decoder.decode(s)
  File "/usr/lib/python3.5/json/decoder.py", line 339, in decode
    obj, end = self.raw_decode(s, idx=_w(s, 0).end())
  File "/usr/lib/python3.5/json/decoder.py", line 357, in raw_decode
    raise JSONDecodeError("Expecting value", s, err.value) from None
json.decoder.JSONDecodeError: Expecting value: line 1 column 1 (char 0)
ERROR:root:get_media_id_by_tag
Traceback (most recent call last):
  File "/home/morteza/Code/instagram_bot/bot/src/instabot.py", line 364, in get_media_id_by_tag
    all_data = json.loads(r.text)
  File "/usr/lib/python3.5/json/__init__.py", line 319, in loads
    return _default_decoder.decode(s)
  File "/usr/lib/python3.5/json/decoder.py", line 339, in decode
    obj, end = self.raw_decode(s, idx=_w(s, 0).end())
  File "/usr/lib/python3.5/json/decoder.py", line 357, in raw_decode
    raise JSONDecodeError("Expecting value", s, err.value) from None
json.decoder.JSONDecodeError: Expecting value: line 1 column 1 (char 0)
ERROR:root:get_media_id_by_tag
Traceback (most recent call last):
  File "/home/morteza/Code/instagram_bot/bot/src/instabot.py", line 364, in get_media_id_by_tag
    all_data = json.loads(r.text)
  File "/usr/lib/python3.5/json/__init__.py", line 319, in loads
    return _default_decoder.decode(s)
  File "/usr/lib/python3.5/json/decoder.py", line 339, in decode
    obj, end = self.raw_decode(s, idx=_w(s, 0).end())
  File "/usr/lib/python3.5/json/decoder.py", line 357, in raw_decode
    raise JSONDecodeError("Expecting value", s, err.value) from None
json.decoder.JSONDecodeError: Expecting value: line 1 column 1 (char 0)
ERROR:root:get_media_id_by_tag
Traceback (most recent call last):
  File "/home/morteza/Code/instagram_bot/bot/src/instabot.py", line 364, in get_media_id_by_tag
    all_data = json.loads(r.text)
  File "/usr/lib/python3.5/json/__init__.py", line 319, in loads
    return _default_decoder.decode(s)
  File "/usr/lib/python3.5/json/decoder.py", line 339, in decode
    obj, end = self.raw_decode(s, idx=_w(s, 0).end())
  File "/usr/lib/python3.5/json/decoder.py", line 357, in raw_decode
    raise JSONDecodeError("Expecting value", s, err.value) from None
json.decoder.JSONDecodeError: Expecting value: line 1 column 1 (char 0)
ERROR:root:get_media_id_by_tag
Traceback (most recent call last):
  File "/home/morteza/Code/instagram_bot/bot/src/instabot.py", line 364, in get_media_id_by_tag
    all_data = json.loads(r.text)
  File "/usr/lib/python3.5/json/__init__.py", line 319, in loads
    return _default_decoder.decode(s)
  File "/usr/lib/python3.5/json/decoder.py", line 339, in decode
    obj, end = self.raw_decode(s, idx=_w(s, 0).end())
  File "/usr/lib/python3.5/json/decoder.py", line 357, in raw_decode
    raise JSONDecodeError("Expecting value", s, err.value) from None
json.decoder.JSONDecodeError: Expecting value: line 1 column 1 (char 0)
ERROR:root:get_media_id_by_tag
Traceback (most recent call last):
  File "/home/morteza/Code/instagram_bot/bot/src/instabot.py", line 364, in get_media_id_by_tag
    all_data = json.loads(r.text)
  File "/usr/lib/python3.5/json/__init__.py", line 319, in loads
    return _default_decoder.decode(s)
  File "/usr/lib/python3.5/json/decoder.py", line 339, in decode
    obj, end = self.raw_decode(s, idx=_w(s, 0).end())
  File "/usr/lib/python3.5/json/decoder.py", line 357, in raw_decode
    raise JSONDecodeError("Expecting value", s, err.value) from None
json.decoder.JSONDecodeError: Expecting value: line 1 column 1 (char 0)
ERROR:root:Except on unfollow... Looks like a network error
Traceback (most recent call last):
  File "/home/morteza/venvs/instapy/lib/python3.5/site-packages/requests/packages/urllib3/connectionpool.py", line 379, in _make_request
    httplib_response = conn.getresponse(buffering=True)
TypeError: getresponse() got an unexpected keyword argument 'buffering'

During handling of the above exception, another exception occurred:

Traceback (most recent call last):
  File "/home/morteza/Code/instagram_bot/bot/src/instabot.py", line 652, in unfollow_on_cleanup
    unfollow = self.s.post(url_unfollow)
  File "/home/morteza/venvs/instapy/lib/python3.5/site-packages/requests/sessions.py", line 535, in post
    return self.request('POST', url, data=data, json=json, **kwargs)
  File "/home/morteza/venvs/instapy/lib/python3.5/site-packages/requests/sessions.py", line 488, in request
    resp = self.send(prep, **send_kwargs)
  File "/home/morteza/venvs/instapy/lib/python3.5/site-packages/requests/sessions.py", line 609, in send
    r = adapter.send(request, **kwargs)
  File "/home/morteza/venvs/instapy/lib/python3.5/site-packages/requests/adapters.py", line 423, in send
    timeout=timeout
  File "/home/morteza/venvs/instapy/lib/python3.5/site-packages/requests/packages/urllib3/connectionpool.py", line 600, in urlopen
    chunked=chunked)
  File "/home/morteza/venvs/instapy/lib/python3.5/site-packages/requests/packages/urllib3/connectionpool.py", line 382, in _make_request
    httplib_response = conn.getresponse()
  File "/usr/lib/python3.5/http/client.py", line 1197, in getresponse
    response.begin()
  File "/usr/lib/python3.5/http/client.py", line 297, in begin
    version, status, reason = self._read_status()
  File "/usr/lib/python3.5/http/client.py", line 258, in _read_status
    line = str(self.fp.readline(_MAXLINE + 1), "iso-8859-1")
  File "/usr/lib/python3.5/socket.py", line 575, in readinto
    return self._sock.recv_into(b)
  File "/usr/lib/python3.5/ssl.py", line 929, in recv_into
    return self.read(nbytes, buffer)
  File "/usr/lib/python3.5/ssl.py", line 791, in read
    return self._sslobj.read(len, buffer)
  File "/usr/lib/python3.5/ssl.py", line 575, in read
    v = self._sslobj.read(len, buffer)
KeyboardInterrupt
ERROR:root:Except on auto_unfollow!
Traceback (most recent call last):
  File "/home/morteza/Code/instagram_bot/bot/src/instabot.py", line 892, in auto_unfollow
    i = 0
  File "/usr/lib/python3.5/json/__init__.py", line 319, in loads
    return _default_decoder.decode(s)
  File "/usr/lib/python3.5/json/decoder.py", line 339, in decode
    obj, end = self.raw_decode(s, idx=_w(s, 0).end())
  File "/usr/lib/python3.5/json/decoder.py", line 357, in raw_decode
    raise JSONDecodeError("Expecting value", s, err.value) from None
json.decoder.JSONDecodeError: Expecting value: line 1 column 1 (char 0)
ERROR:root:Except on auto_unfollow!
Traceback (most recent call last):
  File "/home/morteza/Code/instagram_bot/bot/src/instabot.py", line 889, in auto_unfollow
    all_data = json.loads(r.text)
  File "/usr/lib/python3.5/json/__init__.py", line 319, in loads
    return _default_decoder.decode(s)
  File "/usr/lib/python3.5/json/decoder.py", line 339, in decode
    obj, end = self.raw_decode(s, idx=_w(s, 0).end())
  File "/usr/lib/python3.5/json/decoder.py", line 357, in raw_decode
    raise JSONDecodeError("Expecting value", s, err.value) from None
json.decoder.JSONDecodeError: Expecting value: line 1 column 1 (char 0)
ERROR:root:Except on get_userinfo_by_name
Traceback (most recent call last):
  File "/home/morteza/Code/instagram_bot/bot/src/instabot.py", line 429, in get_userinfo_by_name
    all_data = json.loads(r.text)
  File "/usr/lib/python3.5/json/__init__.py", line 319, in loads
    return _default_decoder.decode(s)
  File "/usr/lib/python3.5/json/decoder.py", line 339, in decode
    obj, end = self.raw_decode(s, idx=_w(s, 0).end())
  File "/usr/lib/python3.5/json/decoder.py", line 357, in raw_decode
    raise JSONDecodeError("Expecting value", s, err.value) from None
json.decoder.JSONDecodeError: Expecting value: line 1 column 1 (char 0)
ERROR:root:Except on get_userinfo_by_name
Traceback (most recent call last):
  File "/home/morteza/Code/instagram_bot/bot/src/instabot.py", line 429, in get_userinfo_by_name
    all_data = json.loads(r.text)
  File "/usr/lib/python3.5/json/__init__.py", line 319, in loads
    return _default_decoder.decode(s)
  File "/usr/lib/python3.5/json/decoder.py", line 339, in decode
    obj, end = self.raw_decode(s, idx=_w(s, 0).end())
  File "/usr/lib/python3.5/json/decoder.py", line 357, in raw_decode
    raise JSONDecodeError("Expecting value", s, err.value) from None
json.decoder.JSONDecodeError: Expecting value: line 1 column 1 (char 0)
ERROR:root:Except on auto_unfollow!
Traceback (most recent call last):
  File "/home/morteza/Code/instagram_bot/bot/src/instabot.py", line 889, in auto_unfollow
    all_data = json.loads(r.text)
  File "/usr/lib/python3.5/json/__init__.py", line 319, in loads
    return _default_decoder.decode(s)
  File "/usr/lib/python3.5/json/decoder.py", line 339, in decode
    obj, end = self.raw_decode(s, idx=_w(s, 0).end())
  File "/usr/lib/python3.5/json/decoder.py", line 357, in raw_decode
    raise JSONDecodeError("Expecting value", s, err.value) from None
json.decoder.JSONDecodeError: Expecting value: line 1 column 1 (char 0)
ERROR:root:Except on auto_unfollow!
Traceback (most recent call last):
  File "/home/morteza/Code/instagram_bot/bot/src/instabot.py", line 889, in auto_unfollow
    all_data = json.loads(r.text)
  File "/usr/lib/python3.5/json/__init__.py", line 319, in loads
    return _default_decoder.decode(s)
  File "/usr/lib/python3.5/json/decoder.py", line 339, in decode
    obj, end = self.raw_decode(s, idx=_w(s, 0).end())
  File "/usr/lib/python3.5/json/decoder.py", line 357, in raw_decode
    raise JSONDecodeError("Expecting value", s, err.value) from None
json.decoder.JSONDecodeError: Expecting value: line 1 column 1 (char 0)
ERROR:root:Except on auto_unfollow!
Traceback (most recent call last):
  File "/home/morteza/Code/instagram_bot/bot/src/instabot.py", line 889, in auto_unfollow
    all_data = json.loads(r.text)
  File "/usr/lib/python3.5/json/__init__.py", line 319, in loads
    return _default_decoder.decode(s)
  File "/usr/lib/python3.5/json/decoder.py", line 339, in decode
    obj, end = self.raw_decode(s, idx=_w(s, 0).end())
  File "/usr/lib/python3.5/json/decoder.py", line 357, in raw_decode
    raise JSONDecodeError("Expecting value", s, err.value) from None
json.decoder.JSONDecodeError: Expecting value: line 1 column 1 (char 0)
ERROR:root:Except on auto_unfollow!
Traceback (most recent call last):
  File "/home/morteza/Code/instagram_bot/bot/src/instabot.py", line 907, in auto_unfollow
    all_data = json.loads(r.text)
  File "/usr/lib/python3.5/json/__init__.py", line 319, in loads
    return _default_decoder.decode(s)
  File "/usr/lib/python3.5/json/decoder.py", line 339, in decode
    obj, end = self.raw_decode(s, idx=_w(s, 0).end())
  File "/usr/lib/python3.5/json/decoder.py", line 357, in raw_decode
    raise JSONDecodeError("Expecting value", s, err.value) from None
json.decoder.JSONDecodeError: Expecting value: line 1 column 1 (char 0)
ERROR:root:Except on auto_unfollow!
Traceback (most recent call last):
  File "/home/morteza/Code/instagram_bot/bot/src/instabot.py", line 907, in auto_unfollow
    all_data = json.loads(r.text)
  File "/usr/lib/python3.5/json/__init__.py", line 319, in loads
    return _default_decoder.decode(s)
  File "/usr/lib/python3.5/json/decoder.py", line 339, in decode
    obj, end = self.raw_decode(s, idx=_w(s, 0).end())
  File "/usr/lib/python3.5/json/decoder.py", line 357, in raw_decode
    raise JSONDecodeError("Expecting value", s, err.value) from None
json.decoder.JSONDecodeError: Expecting value: line 1 column 1 (char 0)
ERROR:root:Except on unfollow... Looks like a network error
Traceback (most recent call last):
  File "/home/morteza/venvs/instapy/lib/python3.5/site-packages/requests/packages/urllib3/connectionpool.py", line 379, in _make_request
    httplib_response = conn.getresponse(buffering=True)
TypeError: getresponse() got an unexpected keyword argument 'buffering'

During handling of the above exception, another exception occurred:

Traceback (most recent call last):
  File "/home/morteza/Code/instagram_bot/bot/src/instabot.py", line 667, in unfollow_on_cleanup
    unfollow = self.s.post(url_unfollow)
  File "/home/morteza/venvs/instapy/lib/python3.5/site-packages/requests/sessions.py", line 535, in post
    return self.request('POST', url, data=data, json=json, **kwargs)
  File "/home/morteza/venvs/instapy/lib/python3.5/site-packages/requests/sessions.py", line 488, in request
    resp = self.send(prep, **send_kwargs)
  File "/home/morteza/venvs/instapy/lib/python3.5/site-packages/requests/sessions.py", line 609, in send
    r = adapter.send(request, **kwargs)
  File "/home/morteza/venvs/instapy/lib/python3.5/site-packages/requests/adapters.py", line 423, in send
    timeout=timeout
  File "/home/morteza/venvs/instapy/lib/python3.5/site-packages/requests/packages/urllib3/connectionpool.py", line 600, in urlopen
    chunked=chunked)
  File "/home/morteza/venvs/instapy/lib/python3.5/site-packages/requests/packages/urllib3/connectionpool.py", line 382, in _make_request
    httplib_response = conn.getresponse()
  File "/usr/lib/python3.5/http/client.py", line 1197, in getresponse
    response.begin()
  File "/usr/lib/python3.5/http/client.py", line 297, in begin
    version, status, reason = self._read_status()
  File "/usr/lib/python3.5/http/client.py", line 258, in _read_status
    line = str(self.fp.readline(_MAXLINE + 1), "iso-8859-1")
  File "/usr/lib/python3.5/socket.py", line 575, in readinto
    return self._sock.recv_into(b)
  File "/usr/lib/python3.5/ssl.py", line 929, in recv_into
    return self.read(nbytes, buffer)
  File "/usr/lib/python3.5/ssl.py", line 791, in read
    return self._sslobj.read(len, buffer)
  File "/usr/lib/python3.5/ssl.py", line 575, in read
    v = self._sslobj.read(len, buffer)
KeyboardInterrupt
ERROR:root:Except on get_userinfo_by_name
Traceback (most recent call last):
  File "/home/morteza/venvs/instapy/lib/python3.5/site-packages/requests/packages/urllib3/connectionpool.py", line 379, in _make_request
    httplib_response = conn.getresponse(buffering=True)
TypeError: getresponse() got an unexpected keyword argument 'buffering'

During handling of the above exception, another exception occurred:

Traceback (most recent call last):
  File "/home/morteza/Code/instagram_bot/bot/src/instabot.py", line 452, in get_userdetail_by_name
    r = self.s.get(url_info)
  File "/home/morteza/venvs/instapy/lib/python3.5/site-packages/requests/sessions.py", line 501, in get
    return self.request('GET', url, **kwargs)
  File "/home/morteza/venvs/instapy/lib/python3.5/site-packages/requests/sessions.py", line 488, in request
    resp = self.send(prep, **send_kwargs)
  File "/home/morteza/venvs/instapy/lib/python3.5/site-packages/requests/sessions.py", line 609, in send
    r = adapter.send(request, **kwargs)
  File "/home/morteza/venvs/instapy/lib/python3.5/site-packages/requests/adapters.py", line 423, in send
    timeout=timeout
  File "/home/morteza/venvs/instapy/lib/python3.5/site-packages/requests/packages/urllib3/connectionpool.py", line 600, in urlopen
    chunked=chunked)
  File "/home/morteza/venvs/instapy/lib/python3.5/site-packages/requests/packages/urllib3/connectionpool.py", line 382, in _make_request
    httplib_response = conn.getresponse()
  File "/usr/lib/python3.5/http/client.py", line 1197, in getresponse
    response.begin()
  File "/usr/lib/python3.5/http/client.py", line 297, in begin
    version, status, reason = self._read_status()
  File "/usr/lib/python3.5/http/client.py", line 258, in _read_status
    line = str(self.fp.readline(_MAXLINE + 1), "iso-8859-1")
  File "/usr/lib/python3.5/socket.py", line 575, in readinto
    return self._sock.recv_into(b)
  File "/usr/lib/python3.5/ssl.py", line 929, in recv_into
    return self.read(nbytes, buffer)
  File "/usr/lib/python3.5/ssl.py", line 791, in read
    return self._sslobj.read(len, buffer)
  File "/usr/lib/python3.5/ssl.py", line 575, in read
    v = self._sslobj.read(len, buffer)
KeyboardInterrupt
ERROR:root:Except on get_userinfo_by_name
Traceback (most recent call last):
  File "/home/morteza/Code/instagram_bot/bot/src/instabot.py", line 452, in get_userdetail_by_name
    r = self.s.get(url_info)
  File "/home/morteza/venvs/instapy/lib/python3.5/site-packages/requests/sessions.py", line 501, in get
    return self.request('GET', url, **kwargs)
  File "/home/morteza/venvs/instapy/lib/python3.5/site-packages/requests/sessions.py", line 488, in request
    resp = self.send(prep, **send_kwargs)
  File "/home/morteza/venvs/instapy/lib/python3.5/site-packages/requests/sessions.py", line 641, in send
    r.content
  File "/home/morteza/venvs/instapy/lib/python3.5/site-packages/requests/models.py", line 797, in content
    self._content = bytes().join(self.iter_content(CONTENT_CHUNK_SIZE)) or bytes()
  File "/home/morteza/venvs/instapy/lib/python3.5/site-packages/requests/models.py", line 719, in generate
    for chunk in self.raw.stream(chunk_size, decode_content=True):
  File "/home/morteza/venvs/instapy/lib/python3.5/site-packages/requests/packages/urllib3/response.py", line 432, in stream
    data = self.read(amt=amt, decode_content=decode_content)
  File "/home/morteza/venvs/instapy/lib/python3.5/site-packages/requests/packages/urllib3/response.py", line 380, in read
    data = self._fp.read(amt)
  File "/usr/lib/python3.5/http/client.py", line 448, in read
    n = self.readinto(b)
  File "/usr/lib/python3.5/http/client.py", line 488, in readinto
    n = self.fp.readinto(b)
  File "/usr/lib/python3.5/socket.py", line 575, in readinto
    return self._sock.recv_into(b)
  File "/usr/lib/python3.5/ssl.py", line 929, in recv_into
    return self.read(nbytes, buffer)
  File "/usr/lib/python3.5/ssl.py", line 791, in read
    return self._sslobj.read(len, buffer)
  File "/usr/lib/python3.5/ssl.py", line 575, in read
    v = self._sslobj.read(len, buffer)
KeyboardInterrupt
ERROR:root:Logout error!
Traceback (most recent call last):
  File "/home/morteza/Code/instagram_bot/bot/src/instabot.py", line 328, in logout
    logout = self.s.post(self.url_logout, data=logout_post)
  File "/home/morteza/venvs/instapy/lib/python3.5/site-packages/requests/sessions.py", line 535, in post
    return self.request('POST', url, data=data, json=json, **kwargs)
  File "/home/morteza/venvs/instapy/lib/python3.5/site-packages/requests/sessions.py", line 488, in request
    resp = self.send(prep, **send_kwargs)
  File "/home/morteza/venvs/instapy/lib/python3.5/site-packages/requests/sessions.py", line 630, in send
    history = [resp for resp in gen] if allow_redirects else []
  File "/home/morteza/venvs/instapy/lib/python3.5/site-packages/requests/sessions.py", line 630, in <listcomp>
    history = [resp for resp in gen] if allow_redirects else []
  File "/home/morteza/venvs/instapy/lib/python3.5/site-packages/requests/sessions.py", line 190, in resolve_redirects
    **adapter_kwargs
  File "/home/morteza/venvs/instapy/lib/python3.5/site-packages/requests/sessions.py", line 641, in send
    r.content
  File "/home/morteza/venvs/instapy/lib/python3.5/site-packages/requests/models.py", line 797, in content
    self._content = bytes().join(self.iter_content(CONTENT_CHUNK_SIZE)) or bytes()
  File "/home/morteza/venvs/instapy/lib/python3.5/site-packages/requests/models.py", line 719, in generate
    for chunk in self.raw.stream(chunk_size, decode_content=True):
  File "/home/morteza/venvs/instapy/lib/python3.5/site-packages/requests/packages/urllib3/response.py", line 432, in stream
    data = self.read(amt=amt, decode_content=decode_content)
  File "/home/morteza/venvs/instapy/lib/python3.5/site-packages/requests/packages/urllib3/response.py", line 380, in read
    data = self._fp.read(amt)
  File "/usr/lib/python3.5/http/client.py", line 448, in read
    n = self.readinto(b)
  File "/usr/lib/python3.5/http/client.py", line 488, in readinto
    n = self.fp.readinto(b)
  File "/usr/lib/python3.5/socket.py", line 575, in readinto
    return self._sock.recv_into(b)
  File "/usr/lib/python3.5/ssl.py", line 929, in recv_into
    return self.read(nbytes, buffer)
  File "/usr/lib/python3.5/ssl.py", line 791, in read
    return self._sslobj.read(len, buffer)
  File "/usr/lib/python3.5/ssl.py", line 575, in read
    v = self._sslobj.read(len, buffer)
KeyboardInterrupt
ERROR:root:Except on get_username_by_user_id
Traceback (most recent call last):
  File "/home/morteza/Code/instagram_bot/bot/src/instabot.py", line 411, in get_username_by_user_id
    r = self.s.get(url_info, headers="")
  File "/home/morteza/venvs/instapy/lib/python3.5/site-packages/requests/sessions.py", line 501, in get
    return self.request('GET', url, **kwargs)
  File "/home/morteza/venvs/instapy/lib/python3.5/site-packages/requests/sessions.py", line 488, in request
    resp = self.send(prep, **send_kwargs)
  File "/home/morteza/venvs/instapy/lib/python3.5/site-packages/requests/sessions.py", line 609, in send
    r = adapter.send(request, **kwargs)
  File "/home/morteza/venvs/instapy/lib/python3.5/site-packages/requests/adapters.py", line 423, in send
    timeout=timeout
  File "/home/morteza/venvs/instapy/lib/python3.5/site-packages/requests/packages/urllib3/connectionpool.py", line 600, in urlopen
    chunked=chunked)
  File "/home/morteza/venvs/instapy/lib/python3.5/site-packages/requests/packages/urllib3/connectionpool.py", line 345, in _make_request
    self._validate_conn(conn)
  File "/home/morteza/venvs/instapy/lib/python3.5/site-packages/requests/packages/urllib3/connectionpool.py", line 844, in _validate_conn
    conn.connect()
  File "/home/morteza/venvs/instapy/lib/python3.5/site-packages/requests/packages/urllib3/connection.py", line 284, in connect
    conn = self._new_conn()
  File "/home/morteza/venvs/instapy/lib/python3.5/site-packages/requests/packages/urllib3/connection.py", line 141, in _new_conn
    (self.host, self.port), self.timeout, **extra_kw)
  File "/home/morteza/venvs/instapy/lib/python3.5/site-packages/requests/packages/urllib3/util/connection.py", line 73, in create_connection
    sock.connect(sa)
KeyboardInterrupt
ERROR:root:Except on follow!
Traceback (most recent call last):
  File "/home/morteza/Code/instagram_bot/bot/src/instabot.py", line 640, in follow
    insert_username(self, user_id=user_id, username=username)
  File "/home/morteza/Code/instagram_bot/bot/src/sql_updates.py", line 74, in insert_username
    VALUES('"+user_id+"','"+username+"','"+ str(now) +"')")
TypeError: Can't convert 'bool' object to str implicitly
ERROR:root:Except on auto_unfollow!
Traceback (most recent call last):
  File "/home/morteza/Code/instagram_bot/bot/src/instabot.py", line 916, in auto_unfollow
    all_data = json.loads(r.text)
  File "/usr/lib/python3.5/json/__init__.py", line 319, in loads
    return _default_decoder.decode(s)
  File "/usr/lib/python3.5/json/decoder.py", line 339, in decode
    obj, end = self.raw_decode(s, idx=_w(s, 0).end())
  File "/usr/lib/python3.5/json/decoder.py", line 357, in raw_decode
    raise JSONDecodeError("Expecting value", s, err.value) from None
json.decoder.JSONDecodeError: Expecting value: line 1 column 1 (char 0)
ERROR:root:get_media_id_by_user
Traceback (most recent call last):
  File "/home/morteza/Code/instagram_bot/bot/src/instabot.py", line 1295, in get_media_id_by_user
    r = self.s.get(url_user)
  File "/home/morteza/venvs/instapy/lib/python3.5/site-packages/requests/sessions.py", line 501, in get
    return self.request('GET', url, **kwargs)
  File "/home/morteza/venvs/instapy/lib/python3.5/site-packages/requests/sessions.py", line 488, in request
    resp = self.send(prep, **send_kwargs)
  File "/home/morteza/venvs/instapy/lib/python3.5/site-packages/requests/sessions.py", line 641, in send
    r.content
  File "/home/morteza/venvs/instapy/lib/python3.5/site-packages/requests/models.py", line 797, in content
    self._content = bytes().join(self.iter_content(CONTENT_CHUNK_SIZE)) or bytes()
  File "/home/morteza/venvs/instapy/lib/python3.5/site-packages/requests/models.py", line 719, in generate
    for chunk in self.raw.stream(chunk_size, decode_content=True):
  File "/home/morteza/venvs/instapy/lib/python3.5/site-packages/requests/packages/urllib3/response.py", line 432, in stream
    data = self.read(amt=amt, decode_content=decode_content)
  File "/home/morteza/venvs/instapy/lib/python3.5/site-packages/requests/packages/urllib3/response.py", line 380, in read
    data = self._fp.read(amt)
  File "/usr/lib/python3.5/http/client.py", line 448, in read
    n = self.readinto(b)
  File "/usr/lib/python3.5/http/client.py", line 488, in readinto
    n = self.fp.readinto(b)
  File "/usr/lib/python3.5/socket.py", line 575, in readinto
    return self._sock.recv_into(b)
  File "/usr/lib/python3.5/ssl.py", line 929, in recv_into
    return self.read(nbytes, buffer)
  File "/usr/lib/python3.5/ssl.py", line 791, in read
    return self._sslobj.read(len, buffer)
  File "/usr/lib/python3.5/ssl.py", line 575, in read
    v = self._sslobj.read(len, buffer)
KeyboardInterrupt
ERROR:root:Except on unfollow... Looks like a network error
Traceback (most recent call last):
  File "/home/morteza/venvs/instapy/lib/python3.5/site-packages/requests/packages/urllib3/connection.py", line 141, in _new_conn
    (self.host, self.port), self.timeout, **extra_kw)
  File "/home/morteza/venvs/instapy/lib/python3.5/site-packages/requests/packages/urllib3/util/connection.py", line 60, in create_connection
    for res in socket.getaddrinfo(host, port, family, socket.SOCK_STREAM):
  File "/usr/lib/python3.5/socket.py", line 732, in getaddrinfo
    for res in _socket.getaddrinfo(host, port, family, type, proto, flags):
socket.gaierror: [Errno -2] Name or service not known

During handling of the above exception, another exception occurred:

Traceback (most recent call last):
  File "/home/morteza/venvs/instapy/lib/python3.5/site-packages/requests/packages/urllib3/connectionpool.py", line 600, in urlopen
    chunked=chunked)
  File "/home/morteza/venvs/instapy/lib/python3.5/site-packages/requests/packages/urllib3/connectionpool.py", line 345, in _make_request
    self._validate_conn(conn)
  File "/home/morteza/venvs/instapy/lib/python3.5/site-packages/requests/packages/urllib3/connectionpool.py", line 844, in _validate_conn
    conn.connect()
  File "/home/morteza/venvs/instapy/lib/python3.5/site-packages/requests/packages/urllib3/connection.py", line 284, in connect
    conn = self._new_conn()
  File "/home/morteza/venvs/instapy/lib/python3.5/site-packages/requests/packages/urllib3/connection.py", line 150, in _new_conn
    self, "Failed to establish a new connection: %s" % e)
requests.packages.urllib3.exceptions.NewConnectionError: <requests.packages.urllib3.connection.VerifiedHTTPSConnection object at 0x7fa7ae00be10>: Failed to establish a new connection: [Errno -2] Name or service not known

During handling of the above exception, another exception occurred:

Traceback (most recent call last):
  File "/home/morteza/venvs/instapy/lib/python3.5/site-packages/requests/adapters.py", line 423, in send
    timeout=timeout
  File "/home/morteza/venvs/instapy/lib/python3.5/site-packages/requests/packages/urllib3/connectionpool.py", line 649, in urlopen
    _stacktrace=sys.exc_info()[2])
  File "/home/morteza/venvs/instapy/lib/python3.5/site-packages/requests/packages/urllib3/util/retry.py", line 376, in increment
    raise MaxRetryError(_pool, url, error or ResponseError(cause))
requests.packages.urllib3.exceptions.MaxRetryError: HTTPSConnectionPool(host='www.instagram.com', port=443): Max retries exceeded with url: /web/friendships/4075239958/unfollow/ (Caused by NewConnectionError('<requests.packages.urllib3.connection.VerifiedHTTPSConnection object at 0x7fa7ae00be10>: Failed to establish a new connection: [Errno -2] Name or service not known',))

During handling of the above exception, another exception occurred:

Traceback (most recent call last):
  File "/home/morteza/Code/instagram_bot/bot/src/instabot.py", line 677, in unfollow_on_cleanup
    unfollow = self.s.post(url_unfollow)
  File "/home/morteza/venvs/instapy/lib/python3.5/site-packages/requests/sessions.py", line 535, in post
    return self.request('POST', url, data=data, json=json, **kwargs)
  File "/home/morteza/venvs/instapy/lib/python3.5/site-packages/requests/sessions.py", line 488, in request
    resp = self.send(prep, **send_kwargs)
  File "/home/morteza/venvs/instapy/lib/python3.5/site-packages/requests/sessions.py", line 609, in send
    r = adapter.send(request, **kwargs)
  File "/home/morteza/venvs/instapy/lib/python3.5/site-packages/requests/adapters.py", line 487, in send
    raise ConnectionError(e, request=request)
requests.exceptions.ConnectionError: HTTPSConnectionPool(host='www.instagram.com', port=443): Max retries exceeded with url: /web/friendships/4075239958/unfollow/ (Caused by NewConnectionError('<requests.packages.urllib3.connection.VerifiedHTTPSConnection object at 0x7fa7ae00be10>: Failed to establish a new connection: [Errno -2] Name or service not known',))
